Workbook
Name AnoCalendario: Calendário!$W$2

Sheet Calendário
B1: MAPA DE EVENTOS MINDSET
U2: Ano: | W2: 2026
B4: ="Janeiro "&AnoCalendario -> Janeiro 2026 | J4: ="Fevereiro "&AnoCalendario -> Fevereiro 2026 | R4: ="Março "&AnoCalendario -> Março 2026 | Z4: Consultar dia
B5: Seg | C5: Ter | D5: Qua | E5: Qui | F5: Sex | G5: Sáb | H5: Dom | J5: Seg | K5: Ter | L5: Qua | M5: Qui | N5: Sex | O5: Sáb | P5: Dom | R5: Seg | S5: Ter | T5: Qua | U5: Qui | V5: Sex | W5: Sáb | X5: Dom | Z5: Data: | AA5: 46290
B6: =IF(MONTH(DATE(AnoCalendario,1,1)-WEEKDAY(DATE(AnoCalendario,1,1),2)+1)=1,DATE(AnoCalendario,1,1)-WEEKDAY(DATE(AnoCalendario,1,1),2)+1,"") | C6: =IF(MONTH(DATE(AnoCalendario,1,1)-WEEKDAY(DATE(AnoCalendario,1,1),2)+2)=1,DATE(AnoCalendario,1,1)-WEEKDAY(DATE(AnoCalendario,1,1),2)+2,"") | D6: =IF(MONTH(DATE(AnoCalendario,1,1)-WEEKDAY(DATE(AnoCalendario,1,1),2)+3)=1,DATE(AnoCalendario,1,1)-WEEKDAY(DATE(AnoCalendario,1,1),2)+3,"") | E6: =IF(MONTH(DATE(AnoCalendario,1,1)-WEEKDAY(DATE(AnoCalendario,1,1),2)+4)=1,DATE(AnoCalendario,1,1)-WEEKDAY(DATE(AnoCalendario,1,1),2)+4,"") -> 46023 | F6: =IF(MONTH(DATE(AnoCalendario,1,1)-WEEKDAY(DATE(AnoCalendario,1,1),2)+5)=1,DATE(AnoCalendario,1,1)-WEEKDAY(DATE(AnoCalendario,1,1),2)+5,"") -> 46024 | G6: =IF(MONTH(DATE(AnoCalendario,1,1)-WEEKDAY(DATE(AnoCalendario,1,1),2)+6)=1,DATE(AnoCalendario,1,1)-WEEKDAY(DATE(AnoCalendario,1,1),2)+6,"") -> 46025 | H6: =IF(MONTH(DATE(AnoCalendario,1,1)-WEEKDAY(DATE(AnoCalendario,1,1),2)+7)=1,DATE(AnoCalendario,1,1)-WEEKDAY(DATE(AnoCalendario,1,1),2)+7,"") -> 46026 | J6: =IF(MONTH(DATE(AnoCalendario,2,1)-WEEKDAY(DATE(AnoCalendario,2,1),2)+1)=2,DATE(AnoCalendario,2,1)-WEEKDAY(DATE(AnoCalendario,2,1),2)+1,"") | K6: =IF(MONTH(DATE(AnoCalendario,2,1)-WEEKDAY(DATE(AnoCalendario,2,1),2)+2)=2,DATE(AnoCalendario,2,1)-WEEKDAY(DATE(AnoCalendario,2,1),2)+2,"") | L6: =IF(MONTH(DATE(AnoCalendario,2,1)-WEEKDAY(DATE(AnoCalendario,2,1),2)+3)=2,DATE(AnoCalendario,2,1)-WEEKDAY(DATE(AnoCalendario,2,1),2)+3,"") | M6: =IF(MONTH(DATE(AnoCalendario,2,1)-WEEKDAY(DATE(AnoCalendario,2,1),2)+4)=2,DATE(AnoCalendario,2,1)-WEEKDAY(DATE(AnoCalendario,2,1),2)+4,"") | N6: =IF(MONTH(DATE(AnoCalendario,2,1)-WEEKDAY(DATE(AnoCalendario,2,1),2)+5)=2,DATE(AnoCalendario,2,1)-WEEKDAY(DATE(AnoCalendario,2,1),2)+5,"") | O6: =IF(MONTH(DATE(AnoCalendario,2,1)-WEEKDAY(DATE(AnoCalendario,2,1),2)+6)=2,DATE(AnoCalendario,2,1)-WEEKDAY(DATE(AnoCalendario,2,1),2)+6,"") | P6: =IF(MONTH(DATE(AnoCalendario,2,1)-WEEKDAY(DATE(AnoCalendario,2,1),2)+7)=2,DATE(AnoCalendario,2,1)-WEEKDAY(DATE(AnoCalendario,2,1),2)+7,"") -> 46054 | R6: =IF(MONTH(DATE(AnoCalendario,3,1)-WEEKDAY(DATE(AnoCalendario,3,1),2)+1)=3,DATE(AnoCalendario,3,1)-WEEKDAY(DATE(AnoCalendario,3,1),2)+1,"") | S6: =IF(MONTH(DATE(AnoCalendario,3,1)-WEEKDAY(DATE(AnoCalendario,3,1),2)+2)=3,DATE(AnoCalendario,3,1)-WEEKDAY(DATE(AnoCalendario,3,1),2)+2,"") | T6: =IF(MONTH(DATE(AnoCalendario,3,1)-WEEKDAY(DATE(AnoCalendario,3,1),2)+3)=3,DATE(AnoCalendario,3,1)-WEEKDAY(DATE(AnoCalendario,3,1),2)+3,"") | U6: =IF(MONTH(DATE(AnoCalendario,3,1)-WEEKDAY(DATE(AnoCalendario,3,1),2)+4)=3,DATE(AnoCalendario,3,1)-WEEKDAY(DATE(AnoCalendario,3,1),2)+4,"") | V6: =IF(MONTH(DATE(AnoCalendario,3,1)-WEEKDAY(DATE(AnoCalendario,3,1),2)+5)=3,DATE(AnoCalendario,3,1)-WEEKDAY(DATE(AnoCalendario,3,1),2)+5,"") | W6: =IF(MONTH(DATE(AnoCalendario,3,1)-WEEKDAY(DATE(AnoCalendario,3,1),2)+6)=3,DATE(AnoCalendario,3,1)-WEEKDAY(DATE(AnoCalendario,3,1),2)+6,"") | X6: =IF(MONTH(DATE(AnoCalendario,3,1)-WEEKDAY(DATE(AnoCalendario,3,1),2)+7)=3,DATE(AnoCalendario,3,1)-WEEKDAY(DATE(AnoCalendario,3,1),2)+7,"") -> 46082 | Z6: N.º de eventos nesse dia: | AA6: =COUNTIF(Eventos!$A$2:$A$999,INT($AA$5)) -> 1
B7: =IF(MONTH(DATE(AnoCalendario,1,1)-WEEKDAY(DATE(AnoCalendario,1,1),2)+8)=1,DATE(AnoCalendario,1,1)-WEEKDAY(DATE(AnoCalendario,1,1),2)+8,"") -> 46027 | C7: =IF(MONTH(DATE(AnoCalendario,1,1)-WEEKDAY(DATE(AnoCalendario,1,1),2)+9)=1,DATE(AnoCalendario,1,1)-WEEKDAY(DATE(AnoCalendario,1,1),2)+9,"") -> 46028 | D7: =IF(MONTH(DATE(AnoCalendario,1,1)-WEEKDAY(DATE(AnoCalendario,1,1),2)+10)=1,DATE(AnoCalendario,1,1)-WEEKDAY(DATE(AnoCalendario,1,1),2)+10,"") -> 46029 | E7: =IF(MONTH(DATE(AnoCalendario,1,1)-WEEKDAY(DATE(AnoCalendario,1,1),2)+11)=1,DATE(AnoCalendario,1,1)-WEEKDAY(DATE(AnoCalendario,1,1),2)+11,"") -> 46030 | F7: =IF(MONTH(DATE(AnoCalendario,1,1)-WEEKDAY(DATE(AnoCalendario,1,1),2)+12)=1,DATE(AnoCalendario,1,1)-WEEKDAY(DATE(AnoCalendario,1,1),2)+12,"") -> 46031 | G7: =IF(MONTH(DATE(AnoCalendario,1,1)-WEEKDAY(DATE(AnoCalendario,1,1),2)+13)=1,DATE(AnoCalendario,1,1)-WEEKDAY(DATE(AnoCalendario,1,1),2)+13,"") -> 46032 | H7: =IF(MONTH(DATE(AnoCalendario,1,1)-WEEKDAY(DATE(AnoCalendario,1,1),2)+14)=1,DATE(AnoCalendario,1,1)-WEEKDAY(DATE(AnoCalendario,1,1),2)+14,"") -> 46033 | J7: =IF(MONTH(DATE(AnoCalendario,2,1)-WEEKDAY(DATE(AnoCalendario,2,1),2)+8)=2,DATE(AnoCalendario,2,1)-WEEKDAY(DATE(AnoCalendario,2,1),2)+8,"") -> 46055 | K7: =IF(MONTH(DATE(AnoCalendario,2,1)-WEEKDAY(DATE(AnoCalendario,2,1),2)+9)=2,DATE(AnoCalendario,2,1)-WEEKDAY(DATE(AnoCalendario,2,1),2)+9,"") -> 46056 | L7: =IF(MONTH(DATE(AnoCalendario,2,1)-WEEKDAY(DATE(AnoCalendario,2,1),2)+10)=2,DATE(AnoCalendario,2,1)-WEEKDAY(DATE(AnoCalendario,2,1),2)+10,"") -> 46057 | M7: =IF(MONTH(DATE(AnoCalendario,2,1)-WEEKDAY(DATE(AnoCalendario,2,1),2)+11)=2,DATE(AnoCalendario,2,1)-WEEKDAY(DATE(AnoCalendario,2,1),2)+11,"") -> 46058 | N7: =IF(MONTH(DATE(AnoCalendario,2,1)-WEEKDAY(DATE(AnoCalendario,2,1),2)+12)=2,DATE(AnoCalendario,2,1)-WEEKDAY(DATE(AnoCalendario,2,1),2)+12,"") -> 46059 | O7: =IF(MONTH(DATE(AnoCalendario,2,1)-WEEKDAY(DATE(AnoCalendario,2,1),2)+13)=2,DATE(AnoCalendario,2,1)-WEEKDAY(DATE(AnoCalendario,2,1),2)+13,"") -> 46060 | P7: =IF(MONTH(DATE(AnoCalendario,2,1)-WEEKDAY(DATE(AnoCalendario,2,1),2)+14)=2,DATE(AnoCalendario,2,1)-WEEKDAY(DATE(AnoCalendario,2,1),2)+14,"") -> 46061 | R7: =IF(MONTH(DATE(AnoCalendario,3,1)-WEEKDAY(DATE(AnoCalendario,3,1),2)+8)=3,DATE(AnoCalendario,3,1)-WEEKDAY(DATE(AnoCalendario,3,1),2)+8,"") -> 46083 | S7: =IF(MONTH(DATE(AnoCalendario,3,1)-WEEKDAY(DATE(AnoCalendario,3,1),2)+9)=3,DATE(AnoCalendario,3,1)-WEEKDAY(DATE(AnoCalendario,3,1),2)+9,"") -> 46084 | T7: =IF(MONTH(DATE(AnoCalendario,3,1)-WEEKDAY(DATE(AnoCalendario,3,1),2)+10)=3,DATE(AnoCalendario,3,1)-WEEKDAY(DATE(AnoCalendario,3,1),2)+10,"") -> 46085 | U7: =IF(MONTH(DATE(AnoCalendario,3,1)-WEEKDAY(DATE(AnoCalendario,3,1),2)+11)=3,DATE(AnoCalendario,3,1)-WEEKDAY(DATE(AnoCalendario,3,1),2)+11,"") -> 46086 | V7: =IF(MONTH(DATE(AnoCalendario,3,1)-WEEKDAY(DATE(AnoCalendario,3,1),2)+12)=3,DATE(AnoCalendario,3,1)-WEEKDAY(DATE(AnoCalendario,3,1),2)+12,"") -> 46087 | W7: =IF(MONTH(DATE(AnoCalendario,3,1)-WEEKDAY(DATE(AnoCalendario,3,1),2)+13)=3,DATE(AnoCalendario,3,1)-WEEKDAY(DATE(AnoCalendario,3,1),2)+13,"") -> 46088 | X7: =IF(MONTH(DATE(AnoCalendario,3,1)-WEEKDAY(DATE(AnoCalendario,3,1),2)+14)=3,DATE(AnoCalendario,3,1)-WEEKDAY(DATE(AnoCalendario,3,1),2)+14,"") -> 46089 | Z7: Evento | AA7: Cliente / Entidade | AB7: Hora | AC7: Estado | AD7: ref.
B8: =IF(MONTH(DATE(AnoCalendario,1,1)-WEEKDAY(DATE(AnoCalendario,1,1),2)+15)=1,DATE(AnoCalendario,1,1)-WEEKDAY(DATE(AnoCalendario,1,1),2)+15,"") -> 46034 | C8: =IF(MONTH(DATE(AnoCalendario,1,1)-WEEKDAY(DATE(AnoCalendario,1,1),2)+16)=1,DATE(AnoCalendario,1,1)-WEEKDAY(DATE(AnoCalendario,1,1),2)+16,"") -> 46035 | D8: =IF(MONTH(DATE(AnoCalendario,1,1)-WEEKDAY(DATE(AnoCalendario,1,1),2)+17)=1,DATE(AnoCalendario,1,1)-WEEKDAY(DATE(AnoCalendario,1,1),2)+17,"") -> 46036 | E8: =IF(MONTH(DATE(AnoCalendario,1,1)-WEEKDAY(DATE(AnoCalendario,1,1),2)+18)=1,DATE(AnoCalendario,1,1)-WEEKDAY(DATE(AnoCalendario,1,1),2)+18,"") -> 46037 | F8: =IF(MONTH(DATE(AnoCalendario,1,1)-WEEKDAY(DATE(AnoCalendario,1,1),2)+19)=1,DATE(AnoCalendario,1,1)-WEEKDAY(DATE(AnoCalendario,1,1),2)+19,"") -> 46038 | G8: =IF(MONTH(DATE(AnoCalendario,1,1)-WEEKDAY(DATE(AnoCalendario,1,1),2)+20)=1,DATE(AnoCalendario,1,1)-WEEKDAY(DATE(AnoCalendario,1,1),2)+20,"") -> 46039 | H8: =IF(MONTH(DATE(AnoCalendario,1,1)-WEEKDAY(DATE(AnoCalendario,1,1),2)+21)=1,DATE(AnoCalendario,1,1)-WEEKDAY(DATE(AnoCalendario,1,1),2)+21,"") -> 46040 | J8: =IF(MONTH(DATE(AnoCalendario,2,1)-WEEKDAY(DATE(AnoCalendario,2,1),2)+15)=2,DATE(AnoCalendario,2,1)-WEEKDAY(DATE(AnoCalendario,2,1),2)+15,"") -> 46062 | K8: =IF(MONTH(DATE(AnoCalendario,2,1)-WEEKDAY(DATE(AnoCalendario,2,1),2)+16)=2,DATE(AnoCalendario,2,1)-WEEKDAY(DATE(AnoCalendario,2,1),2)+16,"") -> 46063 | L8: =IF(MONTH(DATE(AnoCalendario,2,1)-WEEKDAY(DATE(AnoCalendario,2,1),2)+17)=2,DATE(AnoCalendario,2,1)-WEEKDAY(DATE(AnoCalendario,2,1),2)+17,"") -> 46064 | M8: =IF(MONTH(DATE(AnoCalendario,2,1)-WEEKDAY(DATE(AnoCalendario,2,1),2)+18)=2,DATE(AnoCalendario,2,1)-WEEKDAY(DATE(AnoCalendario,2,1),2)+18,"") -> 46065 | N8: =IF(MONTH(DATE(AnoCalendario,2,1)-WEEKDAY(DATE(AnoCalendario,2,1),2)+19)=2,DATE(AnoCalendario,2,1)-WEEKDAY(DATE(AnoCalendario,2,1),2)+19,"") -> 46066 | O8: =IF(MONTH(DATE(AnoCalendario,2,1)-WEEKDAY(DATE(AnoCalendario,2,1),2)+20)=2,DATE(AnoCalendario,2,1)-WEEKDAY(DATE(AnoCalendario,2,1),2)+20,"") -> 46067 | P8: =IF(MONTH(DATE(AnoCalendario,2,1)-WEEKDAY(DATE(AnoCalendario,2,1),2)+21)=2,DATE(AnoCalendario,2,1)-WEEKDAY(DATE(AnoCalendario,2,1),2)+21,"") -> 46068 | R8: =IF(MONTH(DATE(AnoCalendario,3,1)-WEEKDAY(DATE(AnoCalendario,3,1),2)+15)=3,DATE(AnoCalendario,3,1)-WEEKDAY(DATE(AnoCalendario,3,1),2)+15,"") -> 46090 | S8: =IF(MONTH(DATE(AnoCalendario,3,1)-WEEKDAY(DATE(AnoCalendario,3,1),2)+16)=3,DATE(AnoCalendario,3,1)-WEEKDAY(DATE(AnoCalendario,3,1),2)+16,"") -> 46091 | T8: =IF(MONTH(DATE(AnoCalendario,3,1)-WEEKDAY(DATE(AnoCalendario,3,1),2)+17)=3,DATE(AnoCalendario,3,1)-WEEKDAY(DATE(AnoCalendario,3,1),2)+17,"") -> 46092 | U8: =IF(MONTH(DATE(AnoCalendario,3,1)-WEEKDAY(DATE(AnoCalendario,3,1),2)+18)=3,DATE(AnoCalendario,3,1)-WEEKDAY(DATE(AnoCalendario,3,1),2)+18,"") -> 46093 | V8: =IF(MONTH(DATE(AnoCalendario,3,1)-WEEKDAY(DATE(AnoCalendario,3,1),2)+19)=3,DATE(AnoCalendario,3,1)-WEEKDAY(DATE(AnoCalendario,3,1),2)+19,"") -> 46094 | W8: =IF(MONTH(DATE(AnoCalendario,3,1)-WEEKDAY(DATE(AnoCalendario,3,1),2)+20)=3,DATE(AnoCalendario,3,1)-WEEKDAY(DATE(AnoCalendario,3,1),2)+20,"") -> 46095 | X8: =IF(MONTH(DATE(AnoCalendario,3,1)-WEEKDAY(DATE(AnoCalendario,3,1),2)+21)=3,DATE(AnoCalendario,3,1)-WEEKDAY(DATE(AnoCalendario,3,1),2)+21,"") -> 46096 | Z8: =IF($AD8="","",INDEX(Eventos!$C$2:$C$999,$AD8)&"") -> Casamento | AA8: =IF($AD8="","",INDEX(Eventos!$D$2:$D$999,$AD8)&"") -> Mauro | AB8: =IF($AD8="","",IF(INDEX(Eventos!$F$2:$F$999,$AD8)="","",TEXT(INDEX(Eventos!$F$2:$F$999,$AD8),"hh:mm"))) -> 12:00 | AC8: =IF($AD8="","",INDEX(Eventos!$H$2:$H$999,$AD8)&"") -> Confirmado | AD8: =IFERROR(MATCH(INT($AA$5)&"-1",Eventos!$L$2:$L$999,0),"") -> 2
B9: =IF(MONTH(DATE(AnoCalendario,1,1)-WEEKDAY(DATE(AnoCalendario,1,1),2)+22)=1,DATE(AnoCalendario,1,1)-WEEKDAY(DATE(AnoCalendario,1,1),2)+22,"") -> 46041 | C9: =IF(MONTH(DATE(AnoCalendario,1,1)-WEEKDAY(DATE(AnoCalendario,1,1),2)+23)=1,DATE(AnoCalendario,1,1)-WEEKDAY(DATE(AnoCalendario,1,1),2)+23,"") -> 46042 | D9: =IF(MONTH(DATE(AnoCalendario,1,1)-WEEKDAY(DATE(AnoCalendario,1,1),2)+24)=1,DATE(AnoCalendario,1,1)-WEEKDAY(DATE(AnoCalendario,1,1),2)+24,"") -> 46043 | E9: =IF(MONTH(DATE(AnoCalendario,1,1)-WEEKDAY(DATE(AnoCalendario,1,1),2)+25)=1,DATE(AnoCalendario,1,1)-WEEKDAY(DATE(AnoCalendario,1,1),2)+25,"") -> 46044 | F9: =IF(MONTH(DATE(AnoCalendario,1,1)-WEEKDAY(DATE(AnoCalendario,1,1),2)+26)=1,DATE(AnoCalendario,1,1)-WEEKDAY(DATE(AnoCalendario,1,1),2)+26,"") -> 46045 | G9: =IF(MONTH(DATE(AnoCalendario,1,1)-WEEKDAY(DATE(AnoCalendario,1,1),2)+27)=1,DATE(AnoCalendario,1,1)-WEEKDAY(DATE(AnoCalendario,1,1),2)+27,"") -> 46046 | H9: =IF(MONTH(DATE(AnoCalendario,1,1)-WEEKDAY(DATE(AnoCalendario,1,1),2)+28)=1,DATE(AnoCalendario,1,1)-WEEKDAY(DATE(AnoCalendario,1,1),2)+28,"") -> 46047 | J9: =IF(MONTH(DATE(AnoCalendario,2,1)-WEEKDAY(DATE(AnoCalendario,2,1),2)+22)=2,DATE(AnoCalendario,2,1)-WEEKDAY(DATE(AnoCalendario,2,1),2)+22,"") -> 46069 | K9: =IF(MONTH(DATE(AnoCalendario,2,1)-WEEKDAY(DATE(AnoCalendario,2,1),2)+23)=2,DATE(AnoCalendario,2,1)-WEEKDAY(DATE(AnoCalendario,2,1),2)+23,"") -> 46070 | L9: =IF(MONTH(DATE(AnoCalendario,2,1)-WEEKDAY(DATE(AnoCalendario,2,1),2)+24)=2,DATE(AnoCalendario,2,1)-WEEKDAY(DATE(AnoCalendario,2,1),2)+24,"") -> 46071 | M9: =IF(MONTH(DATE(AnoCalendario,2,1)-WEEKDAY(DATE(AnoCalendario,2,1),2)+25)=2,DATE(AnoCalendario,2,1)-WEEKDAY(DATE(AnoCalendario,2,1),2)+25,"") -> 46072 | N9: =IF(MONTH(DATE(AnoCalendario,2,1)-WEEKDAY(DATE(AnoCalendario,2,1),2)+26)=2,DATE(AnoCalendario,2,1)-WEEKDAY(DATE(AnoCalendario,2,1),2)+26,"") -> 46073 | O9: =IF(MONTH(DATE(AnoCalendario,2,1)-WEEKDAY(DATE(AnoCalendario,2,1),2)+27)=2,DATE(AnoCalendario,2,1)-WEEKDAY(DATE(AnoCalendario,2,1),2)+27,"") -> 46074 | P9: =IF(MONTH(DATE(AnoCalendario,2,1)-WEEKDAY(DATE(AnoCalendario,2,1),2)+28)=2,DATE(AnoCalendario,2,1)-WEEKDAY(DATE(AnoCalendario,2,1),2)+28,"") -> 46075 | R9: =IF(MONTH(DATE(AnoCalendario,3,1)-WEEKDAY(DATE(AnoCalendario,3,1),2)+22)=3,DATE(AnoCalendario,3,1)-WEEKDAY(DATE(AnoCalendario,3,1),2)+22,"") -> 46097 | S9: =IF(MONTH(DATE(AnoCalendario,3,1)-WEEKDAY(DATE(AnoCalendario,3,1),2)+23)=3,DATE(AnoCalendario,3,1)-WEEKDAY(DATE(AnoCalendario,3,1),2)+23,"") -> 46098 | T9: =IF(MONTH(DATE(AnoCalendario,3,1)-WEEKDAY(DATE(AnoCalendario,3,1),2)+24)=3,DATE(AnoCalendario,3,1)-WEEKDAY(DATE(AnoCalendario,3,1),2)+24,"") -> 46099 | U9: =IF(MONTH(DATE(AnoCalendario,3,1)-WEEKDAY(DATE(AnoCalendario,3,1),2)+25)=3,DATE(AnoCalendario,3,1)-WEEKDAY(DATE(AnoCalendario,3,1),2)+25,"") -> 46100 | V9: =IF(MONTH(DATE(AnoCalendario,3,1)-WEEKDAY(DATE(AnoCalendario,3,1),2)+26)=3,DATE(AnoCalendario,3,1)-WEEKDAY(DATE(AnoCalendario,3,1),2)+26,"") -> 46101 | W9: =IF(MONTH(DATE(AnoCalendario,3,1)-WEEKDAY(DATE(AnoCalendario,3,1),2)+27)=3,DATE(AnoCalendario,3,1)-WEEKDAY(DATE(AnoCalendario,3,1),2)+27,"") -> 46102 | X9: =IF(MONTH(DATE(AnoCalendario,3,1)-WEEKDAY(DATE(AnoCalendario,3,1),2)+28)=3,DATE(AnoCalendario,3,1)-WEEKDAY(DATE(AnoCalendario,3,1),2)+28,"") -> 46103 | Z9: =IF($AD9="","",INDEX(Eventos!$C$2:$C$999,$AD9)&"") | AA9: =IF($AD9="","",INDEX(Eventos!$D$2:$D$999,$AD9)&"") | AB9: =IF($AD9="","",IF(INDEX(Eventos!$F$2:$F$999,$AD9)="","",TEXT(INDEX(Eventos!$F$2:$F$999,$AD9),"hh:mm"))) | AC9: =IF($AD9="","",INDEX(Eventos!$H$2:$H$999,$AD9)&"") | AD9: =IFERROR(MATCH(INT($AA$5)&"-2",Eventos!$L$2:$L$999,0),"")
B10: =IF(MONTH(DATE(AnoCalendario,1,1)-WEEKDAY(DATE(AnoCalendario,1,1),2)+29)=1,DATE(AnoCalendario,1,1)-WEEKDAY(DATE(AnoCalendario,1,1),2)+29,"") -> 46048 | C10: =IF(MONTH(DATE(AnoCalendario,1,1)-WEEKDAY(DATE(AnoCalendario,1,1),2)+30)=1,DATE(AnoCalendario,1,1)-WEEKDAY(DATE(AnoCalendario,1,1),2)+30,"") -> 46049 | D10: =IF(MONTH(DATE(AnoCalendario,1,1)-WEEKDAY(DATE(AnoCalendario,1,1),2)+31)=1,DATE(AnoCalendario,1,1)-WEEKDAY(DATE(AnoCalendario,1,1),2)+31,"") -> 46050 | E10: =IF(MONTH(DATE(AnoCalendario,1,1)-WEEKDAY(DATE(AnoCalendario,1,1),2)+32)=1,DATE(AnoCalendario,1,1)-WEEKDAY(DATE(AnoCalendario,1,1),2)+32,"") -> 46051 | F10: =IF(MONTH(DATE(AnoCalendario,1,1)-WEEKDAY(DATE(AnoCalendario,1,1),2)+33)=1,DATE(AnoCalendario,1,1)-WEEKDAY(DATE(AnoCalendario,1,1),2)+33,"") -> 46052 | G10: =IF(MONTH(DATE(AnoCalendario,1,1)-WEEKDAY(DATE(AnoCalendario,1,1),2)+34)=1,DATE(AnoCalendario,1,1)-WEEKDAY(DATE(AnoCalendario,1,1),2)+34,"") -> 46053 | H10: =IF(MONTH(DATE(AnoCalendario,1,1)-WEEKDAY(DATE(AnoCalendario,1,1),2)+35)=1,DATE(AnoCalendario,1,1)-WEEKDAY(DATE(AnoCalendario,1,1),2)+35,"") | J10: =IF(MONTH(DATE(AnoCalendario,2,1)-WEEKDAY(DATE(AnoCalendario,2,1),2)+29)=2,DATE(AnoCalendario,2,1)-WEEKDAY(DATE(AnoCalendario,2,1),2)+29,"") -> 46076 | K10: =IF(MONTH(DATE(AnoCalendario,2,1)-WEEKDAY(DATE(AnoCalendario,2,1),2)+30)=2,DATE(AnoCalendario,2,1)-WEEKDAY(DATE(AnoCalendario,2,1),2)+30,"") -> 46077 | L10: =IF(MONTH(DATE(AnoCalendario,2,1)-WEEKDAY(DATE(AnoCalendario,2,1),2)+31)=2,DATE(AnoCalendario,2,1)-WEEKDAY(DATE(AnoCalendario,2,1),2)+31,"") -> 46078 | M10: =IF(MONTH(DATE(AnoCalendario,2,1)-WEEKDAY(DATE(AnoCalendario,2,1),2)+32)=2,DATE(AnoCalendario,2,1)-WEEKDAY(DATE(AnoCalendario,2,1),2)+32,"") -> 46079 | N10: =IF(MONTH(DATE(AnoCalendario,2,1)-WEEKDAY(DATE(AnoCalendario,2,1),2)+33)=2,DATE(AnoCalendario,2,1)-WEEKDAY(DATE(AnoCalendario,2,1),2)+33,"") -> 46080 | O10: =IF(MONTH(DATE(AnoCalendario,2,1)-WEEKDAY(DATE(AnoCalendario,2,1),2)+34)=2,DATE(AnoCalendario,2,1)-WEEKDAY(DATE(AnoCalendario,2,1),2)+34,"") -> 46081 | P10: =IF(MONTH(DATE(AnoCalendario,2,1)-WEEKDAY(DATE(AnoCalendario,2,1),2)+35)=2,DATE(AnoCalendario,2,1)-WEEKDAY(DATE(AnoCalendario,2,1),2)+35,"") | R10: =IF(MONTH(DATE(AnoCalendario,3,1)-WEEKDAY(DATE(AnoCalendario,3,1),2)+29)=3,DATE(AnoCalendario,3,1)-WEEKDAY(DATE(AnoCalendario,3,1),2)+29,"") -> 46104 | S10: =IF(MONTH(DATE(AnoCalendario,3,1)-WEEKDAY(DATE(AnoCalendario,3,1),2)+30)=3,DATE(AnoCalendario,3,1)-WEEKDAY(DATE(AnoCalendario,3,1),2)+30,"") -> 46105 | T10: =IF(MONTH(DATE(AnoCalendario,3,1)-WEEKDAY(DATE(AnoCalendario,3,1),2)+31)=3,DATE(AnoCalendario,3,1)-WEEKDAY(DATE(AnoCalendario,3,1),2)+31,"") -> 46106 | U10: =IF(MONTH(DATE(AnoCalendario,3,1)-WEEKDAY(DATE(AnoCalendario,3,1),2)+32)=3,DATE(AnoCalendario,3,1)-WEEKDAY(DATE(AnoCalendario,3,1),2)+32,"") -> 46107 | V10: =IF(MONTH(DATE(AnoCalendario,3,1)-WEEKDAY(DATE(AnoCalendario,3,1),2)+33)=3,DATE(AnoCalendario,3,1)-WEEKDAY(DATE(AnoCalendario,3,1),2)+33,"") -> 46108 | W10: =IF(MONTH(DATE(AnoCalendario,3,1)-WEEKDAY(DATE(AnoCalendario,3,1),2)+34)=3,DATE(AnoCalendario,3,1)-WEEKDAY(DATE(AnoCalendario,3,1),2)+34,"") -> 46109 | X10: =IF(MONTH(DATE(AnoCalendario,3,1)-WEEKDAY(DATE(AnoCalendario,3,1),2)+35)=3,DATE(AnoCalendario,3,1)-WEEKDAY(DATE(AnoCalendario,3,1),2)+35,"") -> 46110 | Z10: =IF($AD10="","",INDEX(Eventos!$C$2:$C$999,$AD10)&"") | AA10: =IF($AD10="","",INDEX(Eventos!$D$2:$D$999,$AD10)&"") | AB10: =IF($AD10="","",IF(INDEX(Eventos!$F$2:$F$999,$AD10)="","",TEXT(INDEX(Eventos!$F$2:$F$999,$AD10),"hh:mm"))) | AC10: =IF($AD10="","",INDEX(Eventos!$H$2:$H$999,$AD10)&"") | AD10: =IFERROR(MATCH(INT($AA$5)&"-3",Eventos!$L$2:$L$999,0),"")
B11: =IF(MONTH(DATE(AnoCalendario,1,1)-WEEKDAY(DATE(AnoCalendario,1,1),2)+36)=1,DATE(AnoCalendario,1,1)-WEEKDAY(DATE(AnoCalendario,1,1),2)+36,"") | C11: =IF(MONTH(DATE(AnoCalendario,1,1)-WEEKDAY(DATE(AnoCalendario,1,1),2)+37)=1,DATE(AnoCalendario,1,1)-WEEKDAY(DATE(AnoCalendario,1,1),2)+37,"") | D11: =IF(MONTH(DATE(AnoCalendario,1,1)-WEEKDAY(DATE(AnoCalendario,1,1),2)+38)=1,DATE(AnoCalendario,1,1)-WEEKDAY(DATE(AnoCalendario,1,1),2)+38,"") | E11: =IF(MONTH(DATE(AnoCalendario,1,1)-WEEKDAY(DATE(AnoCalendario,1,1),2)+39)=1,DATE(AnoCalendario,1,1)-WEEKDAY(DATE(AnoCalendario,1,1),2)+39,"") | F11: =IF(MONTH(DATE(AnoCalendario,1,1)-WEEKDAY(DATE(AnoCalendario,1,1),2)+40)=1,DATE(AnoCalendario,1,1)-WEEKDAY(DATE(AnoCalendario,1,1),2)+40,"") | G11: =IF(MONTH(DATE(AnoCalendario,1,1)-WEEKDAY(DATE(AnoCalendario,1,1),2)+41)=1,DATE(AnoCalendario,1,1)-WEEKDAY(DATE(AnoCalendario,1,1),2)+41,"") | H11: =IF(MONTH(DATE(AnoCalendario,1,1)-WEEKDAY(DATE(AnoCalendario,1,1),2)+42)=1,DATE(AnoCalendario,1,1)-WEEKDAY(DATE(AnoCalendario,1,1),2)+42,"") | J11: =IF(MONTH(DATE(AnoCalendario,2,1)-WEEKDAY(DATE(AnoCalendario,2,1),2)+36)=2,DATE(AnoCalendario,2,1)-WEEKDAY(DATE(AnoCalendario,2,1),2)+36,"") | K11: =IF(MONTH(DATE(AnoCalendario,2,1)-WEEKDAY(DATE(AnoCalendario,2,1),2)+37)=2,DATE(AnoCalendario,2,1)-WEEKDAY(DATE(AnoCalendario,2,1),2)+37,"") | L11: =IF(MONTH(DATE(AnoCalendario,2,1)-WEEKDAY(DATE(AnoCalendario,2,1),2)+38)=2,DATE(AnoCalendario,2,1)-WEEKDAY(DATE(AnoCalendario,2,1),2)+38,"") | M11: =IF(MONTH(DATE(AnoCalendario,2,1)-WEEKDAY(DATE(AnoCalendario,2,1),2)+39)=2,DATE(AnoCalendario,2,1)-WEEKDAY(DATE(AnoCalendario,2,1),2)+39,"") | N11: =IF(MONTH(DATE(AnoCalendario,2,1)-WEEKDAY(DATE(AnoCalendario,2,1),2)+40)=2,DATE(AnoCalendario,2,1)-WEEKDAY(DATE(AnoCalendario,2,1),2)+40,"") | O11: =IF(MONTH(DATE(AnoCalendario,2,1)-WEEKDAY(DATE(AnoCalendario,2,1),2)+41)=2,DATE(AnoCalendario,2,1)-WEEKDAY(DATE(AnoCalendario,2,1),2)+41,"") | P11: =IF(MONTH(DATE(AnoCalendario,2,1)-WEEKDAY(DATE(AnoCalendario,2,1),2)+42)=2,DATE(AnoCalendario,2,1)-WEEKDAY(DATE(AnoCalendario,2,1),2)+42,"") | R11: =IF(MONTH(DATE(AnoCalendario,3,1)-WEEKDAY(DATE(AnoCalendario,3,1),2)+36)=3,DATE(AnoCalendario,3,1)-WEEKDAY(DATE(AnoCalendario,3,1),2)+36,"") -> 46111 | S11: =IF(MONTH(DATE(AnoCalendario,3,1)-WEEKDAY(DATE(AnoCalendario,3,1),2)+37)=3,DATE(AnoCalendario,3,1)-WEEKDAY(DATE(AnoCalendario,3,1),2)+37,"") -> 46112 | T11: =IF(MONTH(DATE(AnoCalendario,3,1)-WEEKDAY(DATE(AnoCalendario,3,1),2)+38)=3,DATE(AnoCalendario,3,1)-WEEKDAY(DATE(AnoCalendario,3,1),2)+38,"") | U11: =IF(MONTH(DATE(AnoCalendario,3,1)-WEEKDAY(DATE(AnoCalendario,3,1),2)+39)=3,DATE(AnoCalendario,3,1)-WEEKDAY(DATE(AnoCalendario,3,1),2)+39,"") | V11: =IF(MONTH(DATE(AnoCalendario,3,1)-WEEKDAY(DATE(AnoCalendario,3,1),2)+40)=3,DATE(AnoCalendario,3,1)-WEEKDAY(DATE(AnoCalendario,3,1),2)+40,"") | W11: =IF(MONTH(DATE(AnoCalendario,3,1)-WEEKDAY(DATE(AnoCalendario,3,1),2)+41)=3,DATE(AnoCalendario,3,1)-WEEKDAY(DATE(AnoCalendario,3,1),2)+41,"") | X11: =IF(MONTH(DATE(AnoCalendario,3,1)-WEEKDAY(DATE(AnoCalendario,3,1),2)+42)=3,DATE(AnoCalendario,3,1)-WEEKDAY(DATE(AnoCalendario,3,1),2)+42,"") | Z11: =IF($AD11="","",INDEX(Eventos!$C$2:$C$999,$AD11)&"") | AA11: =IF($AD11="","",INDEX(Eventos!$D$2:$D$999,$AD11)&"") | AB11: =IF($AD11="","",IF(INDEX(Eventos!$F$2:$F$999,$AD11)="","",TEXT(INDEX(Eventos!$F$2:$F$999,$AD11),"hh:mm"))) | AC11: =IF($AD11="","",INDEX(Eventos!$H$2:$H$999,$AD11)&"") | AD11: =IFERROR(MATCH(INT($AA$5)&"-4",Eventos!$L$2:$L$999,0),"")
B12: ="Eventos: "&COUNTIFS(Eventos!$A$2:$A$999,">="&DATE(AnoCalendario,1,1),Eventos!$A$2:$A$999,"<"&DATE(AnoCalendario,2,1),Eventos!$H$2:$H$999,"<>Cancelado") -> Eventos: 0 | J12: ="Eventos: "&COUNTIFS(Eventos!$A$2:$A$999,">="&DATE(AnoCalendario,2,1),Eventos!$A$2:$A$999,"<"&DATE(AnoCalendario,3,1),Eventos!$H$2:$H$999,"<>Cancelado") -> Eventos: 0 | R12: ="Eventos: "&COUNTIFS(Eventos!$A$2:$A$999,">="&DATE(AnoCalendario,3,1),Eventos!$A$2:$A$999,"<"&DATE(AnoCalendario,4,1),Eventos!$H$2:$H$999,"<>Cancelado") -> Eventos: 0 | Z12: =IF(AA6>4,"+ "&(AA6-4)&" evento(s) — ver folha Eventos","")
Z13: Escreva uma data na célula amarela para ver os eventos desse dia.
B14: ="Abril "&AnoCalendario -> Abril 2026 | J14: ="Maio "&AnoCalendario -> Maio 2026 | R14: ="Junho "&AnoCalendario -> Junho 2026
B15: Seg | C15: Ter | D15: Qua | E15: Qui | F15: Sex | G15: Sáb | H15: Dom | J15: Seg | K15: Ter | L15: Qua | M15: Qui | N15: Sex | O15: Sáb | P15: Dom | R15: Seg | S15: Ter | T15: Qua | U15: Qui | V15: Sex | W15: Sáb | X15: Dom
B16: =IF(MONTH(DATE(AnoCalendario,4,1)-WEEKDAY(DATE(AnoCalendario,4,1),2)+1)=4,DATE(AnoCalendario,4,1)-WEEKDAY(DATE(AnoCalendario,4,1),2)+1,"") | C16: =IF(MONTH(DATE(AnoCalendario,4,1)-WEEKDAY(DATE(AnoCalendario,4,1),2)+2)=4,DATE(AnoCalendario,4,1)-WEEKDAY(DATE(AnoCalendario,4,1),2)+2,"") | D16: =IF(MONTH(DATE(AnoCalendario,4,1)-WEEKDAY(DATE(AnoCalendario,4,1),2)+3)=4,DATE(AnoCalendario,4,1)-WEEKDAY(DATE(AnoCalendario,4,1),2)+3,"") -> 46113 | E16: =IF(MONTH(DATE(AnoCalendario,4,1)-WEEKDAY(DATE(AnoCalendario,4,1),2)+4)=4,DATE(AnoCalendario,4,1)-WEEKDAY(DATE(AnoCalendario,4,1),2)+4,"") -> 46114 | F16: =IF(MONTH(DATE(AnoCalendario,4,1)-WEEKDAY(DATE(AnoCalendario,4,1),2)+5)=4,DATE(AnoCalendario,4,1)-WEEKDAY(DATE(AnoCalendario,4,1),2)+5,"") -> 46115 | G16: =IF(MONTH(DATE(AnoCalendario,4,1)-WEEKDAY(DATE(AnoCalendario,4,1),2)+6)=4,DATE(AnoCalendario,4,1)-WEEKDAY(DATE(AnoCalendario,4,1),2)+6,"") -> 46116 | H16: =IF(MONTH(DATE(AnoCalendario,4,1)-WEEKDAY(DATE(AnoCalendario,4,1),2)+7)=4,DATE(AnoCalendario,4,1)-WEEKDAY(DATE(AnoCalendario,4,1),2)+7,"") -> 46117 | J16: =IF(MONTH(DATE(AnoCalendario,5,1)-WEEKDAY(DATE(AnoCalendario,5,1),2)+1)=5,DATE(AnoCalendario,5,1)-WEEKDAY(DATE(AnoCalendario,5,1),2)+1,"") | K16: =IF(MONTH(DATE(AnoCalendario,5,1)-WEEKDAY(DATE(AnoCalendario,5,1),2)+2)=5,DATE(AnoCalendario,5,1)-WEEKDAY(DATE(AnoCalendario,5,1),2)+2,"") | L16: =IF(MONTH(DATE(AnoCalendario,5,1)-WEEKDAY(DATE(AnoCalendario,5,1),2)+3)=5,DATE(AnoCalendario,5,1)-WEEKDAY(DATE(AnoCalendario,5,1),2)+3,"") | M16: =IF(MONTH(DATE(AnoCalendario,5,1)-WEEKDAY(DATE(AnoCalendario,5,1),2)+4)=5,DATE(AnoCalendario,5,1)-WEEKDAY(DATE(AnoCalendario,5,1),2)+4,"") | N16: =IF(MONTH(DATE(AnoCalendario,5,1)-WEEKDAY(DATE(AnoCalendario,5,1),2)+5)=5,DATE(AnoCalendario,5,1)-WEEKDAY(DATE(AnoCalendario,5,1),2)+5,"") -> 46143 | O16: =IF(MONTH(DATE(AnoCalendario,5,1)-WEEKDAY(DATE(AnoCalendario,5,1),2)+6)=5,DATE(AnoCalendario,5,1)-WEEKDAY(DATE(AnoCalendario,5,1),2)+6,"") -> 46144 | P16: =IF(MONTH(DATE(AnoCalendario,5,1)-WEEKDAY(DATE(AnoCalendario,5,1),2)+7)=5,DATE(AnoCalendario,5,1)-WEEKDAY(DATE(AnoCalendario,5,1),2)+7,"") -> 46145 | R16: =IF(MONTH(DATE(AnoCalendario,6,1)-WEEKDAY(DATE(AnoCalendario,6,1),2)+1)=6,DATE(AnoCalendario,6,1)-WEEKDAY(DATE(AnoCalendario,6,1),2)+1,"") -> 46174 | S16: =IF(MONTH(DATE(AnoCalendario,6,1)-WEEKDAY(DATE(AnoCalendario,6,1),2)+2)=6,DATE(AnoCalendario,6,1)-WEEKDAY(DATE(AnoCalendario,6,1),2)+2,"") -> 46175 | T16: =IF(MONTH(DATE(AnoCalendario,6,1)-WEEKDAY(DATE(AnoCalendario,6,1),2)+3)=6,DATE(AnoCalendario,6,1)-WEEKDAY(DATE(AnoCalendario,6,1),2)+3,"") -> 46176 | U16: =IF(MONTH(DATE(AnoCalendario,6,1)-WEEKDAY(DATE(AnoCalendario,6,1),2)+4)=6,DATE(AnoCalendario,6,1)-WEEKDAY(DATE(AnoCalendario,6,1),2)+4,"") -> 46177 | V16: =IF(MONTH(DATE(AnoCalendario,6,1)-WEEKDAY(DATE(AnoCalendario,6,1),2)+5)=6,DATE(AnoCalendario,6,1)-WEEKDAY(DATE(AnoCalendario,6,1),2)+5,"") -> 46178 | W16: =IF(MONTH(DATE(AnoCalendario,6,1)-WEEKDAY(DATE(AnoCalendario,6,1),2)+6)=6,DATE(AnoCalendario,6,1)-WEEKDAY(DATE(AnoCalendario,6,1),2)+6,"") -> 46179 | X16: =IF(MONTH(DATE(AnoCalendario,6,1)-WEEKDAY(DATE(AnoCalendario,6,1),2)+7)=6,DATE(AnoCalendario,6,1)-WEEKDAY(DATE(AnoCalendario,6,1),2)+7,"") -> 46180
B17: =IF(MONTH(DATE(AnoCalendario,4,1)-WEEKDAY(DATE(AnoCalendario,4,1),2)+8)=4,DATE(AnoCalendario,4,1)-WEEKDAY(DATE(AnoCalendario,4,1),2)+8,"") -> 46118 | C17: =IF(MONTH(DATE(AnoCalendario,4,1)-WEEKDAY(DATE(AnoCalendario,4,1),2)+9)=4,DATE(AnoCalendario,4,1)-WEEKDAY(DATE(AnoCalendario,4,1),2)+9,"") -> 46119 | D17: =IF(MONTH(DATE(AnoCalendario,4,1)-WEEKDAY(DATE(AnoCalendario,4,1),2)+10)=4,DATE(AnoCalendario,4,1)-WEEKDAY(DATE(AnoCalendario,4,1),2)+10,"") -> 46120 | E17: =IF(MONTH(DATE(AnoCalendario,4,1)-WEEKDAY(DATE(AnoCalendario,4,1),2)+11)=4,DATE(AnoCalendario,4,1)-WEEKDAY(DATE(AnoCalendario,4,1),2)+11,"") -> 46121 | F17: =IF(MONTH(DATE(AnoCalendario,4,1)-WEEKDAY(DATE(AnoCalendario,4,1),2)+12)=4,DATE(AnoCalendario,4,1)-WEEKDAY(DATE(AnoCalendario,4,1),2)+12,"") -> 46122 | G17: =IF(MONTH(DATE(AnoCalendario,4,1)-WEEKDAY(DATE(AnoCalendario,4,1),2)+13)=4,DATE(AnoCalendario,4,1)-WEEKDAY(DATE(AnoCalendario,4,1),2)+13,"") -> 46123 | H17: =IF(MONTH(DATE(AnoCalendario,4,1)-WEEKDAY(DATE(AnoCalendario,4,1),2)+14)=4,DATE(AnoCalendario,4,1)-WEEKDAY(DATE(AnoCalendario,4,1),2)+14,"") -> 46124 | J17: =IF(MONTH(DATE(AnoCalendario,5,1)-WEEKDAY(DATE(AnoCalendario,5,1),2)+8)=5,DATE(AnoCalendario,5,1)-WEEKDAY(DATE(AnoCalendario,5,1),2)+8,"") -> 46146 | K17: =IF(MONTH(DATE(AnoCalendario,5,1)-WEEKDAY(DATE(AnoCalendario,5,1),2)+9)=5,DATE(AnoCalendario,5,1)-WEEKDAY(DATE(AnoCalendario,5,1),2)+9,"") -> 46147 | L17: =IF(MONTH(DATE(AnoCalendario,5,1)-WEEKDAY(DATE(AnoCalendario,5,1),2)+10)=5,DATE(AnoCalendario,5,1)-WEEKDAY(DATE(AnoCalendario,5,1),2)+10,"") -> 46148 | M17: =IF(MONTH(DATE(AnoCalendario,5,1)-WEEKDAY(DATE(AnoCalendario,5,1),2)+11)=5,DATE(AnoCalendario,5,1)-WEEKDAY(DATE(AnoCalendario,5,1),2)+11,"") -> 46149 | N17: =IF(MONTH(DATE(AnoCalendario,5,1)-WEEKDAY(DATE(AnoCalendario,5,1),2)+12)=5,DATE(AnoCalendario,5,1)-WEEKDAY(DATE(AnoCalendario,5,1),2)+12,"") -> 46150 | O17: =IF(MONTH(DATE(AnoCalendario,5,1)-WEEKDAY(DATE(AnoCalendario,5,1),2)+13)=5,DATE(AnoCalendario,5,1)-WEEKDAY(DATE(AnoCalendario,5,1),2)+13,"") -> 46151 | P17: =IF(MONTH(DATE(AnoCalendario,5,1)-WEEKDAY(DATE(AnoCalendario,5,1),2)+14)=5,DATE(AnoCalendario,5,1)-WEEKDAY(DATE(AnoCalendario,5,1),2)+14,"") -> 46152 | R17: =IF(MONTH(DATE(AnoCalendario,6,1)-WEEKDAY(DATE(AnoCalendario,6,1),2)+8)=6,DATE(AnoCalendario,6,1)-WEEKDAY(DATE(AnoCalendario,6,1),2)+8,"") -> 46181 | S17: =IF(MONTH(DATE(AnoCalendario,6,1)-WEEKDAY(DATE(AnoCalendario,6,1),2)+9)=6,DATE(AnoCalendario,6,1)-WEEKDAY(DATE(AnoCalendario,6,1),2)+9,"") -> 46182 | T17: =IF(MONTH(DATE(AnoCalendario,6,1)-WEEKDAY(DATE(AnoCalendario,6,1),2)+10)=6,DATE(AnoCalendario,6,1)-WEEKDAY(DATE(AnoCalendario,6,1),2)+10,"") -> 46183 | U17: =IF(MONTH(DATE(AnoCalendario,6,1)-WEEKDAY(DATE(AnoCalendario,6,1),2)+11)=6,DATE(AnoCalendario,6,1)-WEEKDAY(DATE(AnoCalendario,6,1),2)+11,"") -> 46184 | V17: =IF(MONTH(DATE(AnoCalendario,6,1)-WEEKDAY(DATE(AnoCalendario,6,1),2)+12)=6,DATE(AnoCalendario,6,1)-WEEKDAY(DATE(AnoCalendario,6,1),2)+12,"") -> 46185 | W17: =IF(MONTH(DATE(AnoCalendario,6,1)-WEEKDAY(DATE(AnoCalendario,6,1),2)+13)=6,DATE(AnoCalendario,6,1)-WEEKDAY(DATE(AnoCalendario,6,1),2)+13,"") -> 46186 | X17: =IF(MONTH(DATE(AnoCalendario,6,1)-WEEKDAY(DATE(AnoCalendario,6,1),2)+14)=6,DATE(AnoCalendario,6,1)-WEEKDAY(DATE(AnoCalendario,6,1),2)+14,"") -> 46187
B18: =IF(MONTH(DATE(AnoCalendario,4,1)-WEEKDAY(DATE(AnoCalendario,4,1),2)+15)=4,DATE(AnoCalendario,4,1)-WEEKDAY(DATE(AnoCalendario,4,1),2)+15,"") -> 46125 | C18: =IF(MONTH(DATE(AnoCalendario,4,1)-WEEKDAY(DATE(AnoCalendario,4,1),2)+16)=4,DATE(AnoCalendario,4,1)-WEEKDAY(DATE(AnoCalendario,4,1),2)+16,"") -> 46126 | D18: =IF(MONTH(DATE(AnoCalendario,4,1)-WEEKDAY(DATE(AnoCalendario,4,1),2)+17)=4,DATE(AnoCalendario,4,1)-WEEKDAY(DATE(AnoCalendario,4,1),2)+17,"") -> 46127 | E18: =IF(MONTH(DATE(AnoCalendario,4,1)-WEEKDAY(DATE(AnoCalendario,4,1),2)+18)=4,DATE(AnoCalendario,4,1)-WEEKDAY(DATE(AnoCalendario,4,1),2)+18,"") -> 46128 | F18: =IF(MONTH(DATE(AnoCalendario,4,1)-WEEKDAY(DATE(AnoCalendario,4,1),2)+19)=4,DATE(AnoCalendario,4,1)-WEEKDAY(DATE(AnoCalendario,4,1),2)+19,"") -> 46129 | G18: =IF(MONTH(DATE(AnoCalendario,4,1)-WEEKDAY(DATE(AnoCalendario,4,1),2)+20)=4,DATE(AnoCalendario,4,1)-WEEKDAY(DATE(AnoCalendario,4,1),2)+20,"") -> 46130 | H18: =IF(MONTH(DATE(AnoCalendario,4,1)-WEEKDAY(DATE(AnoCalendario,4,1),2)+21)=4,DATE(AnoCalendario,4,1)-WEEKDAY(DATE(AnoCalendario,4,1),2)+21,"") -> 46131 | J18: =IF(MONTH(DATE(AnoCalendario,5,1)-WEEKDAY(DATE(AnoCalendario,5,1),2)+15)=5,DATE(AnoCalendario,5,1)-WEEKDAY(DATE(AnoCalendario,5,1),2)+15,"") -> 46153 | K18: =IF(MONTH(DATE(AnoCalendario,5,1)-WEEKDAY(DATE(AnoCalendario,5,1),2)+16)=5,DATE(AnoCalendario,5,1)-WEEKDAY(DATE(AnoCalendario,5,1),2)+16,"") -> 46154 | L18: =IF(MONTH(DATE(AnoCalendario,5,1)-WEEKDAY(DATE(AnoCalendario,5,1),2)+17)=5,DATE(AnoCalendario,5,1)-WEEKDAY(DATE(AnoCalendario,5,1),2)+17,"") -> 46155 | M18: =IF(MONTH(DATE(AnoCalendario,5,1)-WEEKDAY(DATE(AnoCalendario,5,1),2)+18)=5,DATE(AnoCalendario,5,1)-WEEKDAY(DATE(AnoCalendario,5,1),2)+18,"") -> 46156 | N18: =IF(MONTH(DATE(AnoCalendario,5,1)-WEEKDAY(DATE(AnoCalendario,5,1),2)+19)=5,DATE(AnoCalendario,5,1)-WEEKDAY(DATE(AnoCalendario,5,1),2)+19,"") -> 46157 | O18: =IF(MONTH(DATE(AnoCalendario,5,1)-WEEKDAY(DATE(AnoCalendario,5,1),2)+20)=5,DATE(AnoCalendario,5,1)-WEEKDAY(DATE(AnoCalendario,5,1),2)+20,"") -> 46158 | P18: =IF(MONTH(DATE(AnoCalendario,5,1)-WEEKDAY(DATE(AnoCalendario,5,1),2)+21)=5,DATE(AnoCalendario,5,1)-WEEKDAY(DATE(AnoCalendario,5,1),2)+21,"") -> 46159 | R18: =IF(MONTH(DATE(AnoCalendario,6,1)-WEEKDAY(DATE(AnoCalendario,6,1),2)+15)=6,DATE(AnoCalendario,6,1)-WEEKDAY(DATE(AnoCalendario,6,1),2)+15,"") -> 46188 | S18: =IF(MONTH(DATE(AnoCalendario,6,1)-WEEKDAY(DATE(AnoCalendario,6,1),2)+16)=6,DATE(AnoCalendario,6,1)-WEEKDAY(DATE(AnoCalendario,6,1),2)+16,"") -> 46189 | T18: =IF(MONTH(DATE(AnoCalendario,6,1)-WEEKDAY(DATE(AnoCalendario,6,1),2)+17)=6,DATE(AnoCalendario,6,1)-WEEKDAY(DATE(AnoCalendario,6,1),2)+17,"") -> 46190 | U18: =IF(MONTH(DATE(AnoCalendario,6,1)-WEEKDAY(DATE(AnoCalendario,6,1),2)+18)=6,DATE(AnoCalendario,6,1)-WEEKDAY(DATE(AnoCalendario,6,1),2)+18,"") -> 46191 | V18: =IF(MONTH(DATE(AnoCalendario,6,1)-WEEKDAY(DATE(AnoCalendario,6,1),2)+19)=6,DATE(AnoCalendario,6,1)-WEEKDAY(DATE(AnoCalendario,6,1),2)+19,"") -> 46192 | W18: =IF(MONTH(DATE(AnoCalendario,6,1)-WEEKDAY(DATE(AnoCalendario,6,1),2)+20)=6,DATE(AnoCalendario,6,1)-WEEKDAY(DATE(AnoCalendario,6,1),2)+20,"") -> 46193 | X18: =IF(MONTH(DATE(AnoCalendario,6,1)-WEEKDAY(DATE(AnoCalendario,6,1),2)+21)=6,DATE(AnoCalendario,6,1)-WEEKDAY(DATE(AnoCalendario,6,1),2)+21,"") -> 46194
B19: =IF(MONTH(DATE(AnoCalendario,4,1)-WEEKDAY(DATE(AnoCalendario,4,1),2)+22)=4,DATE(AnoCalendario,4,1)-WEEKDAY(DATE(AnoCalendario,4,1),2)+22,"") -> 46132 | C19: =IF(MONTH(DATE(AnoCalendario,4,1)-WEEKDAY(DATE(AnoCalendario,4,1),2)+23)=4,DATE(AnoCalendario,4,1)-WEEKDAY(DATE(AnoCalendario,4,1),2)+23,"") -> 46133 | D19: =IF(MONTH(DATE(AnoCalendario,4,1)-WEEKDAY(DATE(AnoCalendario,4,1),2)+24)=4,DATE(AnoCalendario,4,1)-WEEKDAY(DATE(AnoCalendario,4,1),2)+24,"") -> 46134 | E19: =IF(MONTH(DATE(AnoCalendario,4,1)-WEEKDAY(DATE(AnoCalendario,4,1),2)+25)=4,DATE(AnoCalendario,4,1)-WEEKDAY(DATE(AnoCalendario,4,1),2)+25,"") -> 46135 | F19: =IF(MONTH(DATE(AnoCalendario,4,1)-WEEKDAY(DATE(AnoCalendario,4,1),2)+26)=4,DATE(AnoCalendario,4,1)-WEEKDAY(DATE(AnoCalendario,4,1),2)+26,"") -> 46136 | G19: =IF(MONTH(DATE(AnoCalendario,4,1)-WEEKDAY(DATE(AnoCalendario,4,1),2)+27)=4,DATE(AnoCalendario,4,1)-WEEKDAY(DATE(AnoCalendario,4,1),2)+27,"") -> 46137 | H19: =IF(MONTH(DATE(AnoCalendario,4,1)-WEEKDAY(DATE(AnoCalendario,4,1),2)+28)=4,DATE(AnoCalendario,4,1)-WEEKDAY(DATE(AnoCalendario,4,1),2)+28,"") -> 46138 | J19: =IF(MONTH(DATE(AnoCalendario,5,1)-WEEKDAY(DATE(AnoCalendario,5,1),2)+22)=5,DATE(AnoCalendario,5,1)-WEEKDAY(DATE(AnoCalendario,5,1),2)+22,"") -> 46160 | K19: =IF(MONTH(DATE(AnoCalendario,5,1)-WEEKDAY(DATE(AnoCalendario,5,1),2)+23)=5,DATE(AnoCalendario,5,1)-WEEKDAY(DATE(AnoCalendario,5,1),2)+23,"") -> 46161 | L19: =IF(MONTH(DATE(AnoCalendario,5,1)-WEEKDAY(DATE(AnoCalendario,5,1),2)+24)=5,DATE(AnoCalendario,5,1)-WEEKDAY(DATE(AnoCalendario,5,1),2)+24,"") -> 46162 | M19: =IF(MONTH(DATE(AnoCalendario,5,1)-WEEKDAY(DATE(AnoCalendario,5,1),2)+25)=5,DATE(AnoCalendario,5,1)-WEEKDAY(DATE(AnoCalendario,5,1),2)+25,"") -> 46163 | N19: =IF(MONTH(DATE(AnoCalendario,5,1)-WEEKDAY(DATE(AnoCalendario,5,1),2)+26)=5,DATE(AnoCalendario,5,1)-WEEKDAY(DATE(AnoCalendario,5,1),2)+26,"") -> 46164 | O19: =IF(MONTH(DATE(AnoCalendario,5,1)-WEEKDAY(DATE(AnoCalendario,5,1),2)+27)=5,DATE(AnoCalendario,5,1)-WEEKDAY(DATE(AnoCalendario,5,1),2)+27,"") -> 46165 | P19: =IF(MONTH(DATE(AnoCalendario,5,1)-WEEKDAY(DATE(AnoCalendario,5,1),2)+28)=5,DATE(AnoCalendario,5,1)-WEEKDAY(DATE(AnoCalendario,5,1),2)+28,"") -> 46166 | R19: =IF(MONTH(DATE(AnoCalendario,6,1)-WEEKDAY(DATE(AnoCalendario,6,1),2)+22)=6,DATE(AnoCalendario,6,1)-WEEKDAY(DATE(AnoCalendario,6,1),2)+22,"") -> 46195 | S19: =IF(MONTH(DATE(AnoCalendario,6,1)-WEEKDAY(DATE(AnoCalendario,6,1),2)+23)=6,DATE(AnoCalendario,6,1)-WEEKDAY(DATE(AnoCalendario,6,1),2)+23,"") -> 46196 | T19: =IF(MONTH(DATE(AnoCalendario,6,1)-WEEKDAY(DATE(AnoCalendario,6,1),2)+24)=6,DATE(AnoCalendario,6,1)-WEEKDAY(DATE(AnoCalendario,6,1),2)+24,"") -> 46197 | U19: =IF(MONTH(DATE(AnoCalendario,6,1)-WEEKDAY(DATE(AnoCalendario,6,1),2)+25)=6,DATE(AnoCalendario,6,1)-WEEKDAY(DATE(AnoCalendario,6,1),2)+25,"") -> 46198 | V19: =IF(MONTH(DATE(AnoCalendario,6,1)-WEEKDAY(DATE(AnoCalendario,6,1),2)+26)=6,DATE(AnoCalendario,6,1)-WEEKDAY(DATE(AnoCalendario,6,1),2)+26,"") -> 46199 | W19: =IF(MONTH(DATE(AnoCalendario,6,1)-WEEKDAY(DATE(AnoCalendario,6,1),2)+27)=6,DATE(AnoCalendario,6,1)-WEEKDAY(DATE(AnoCalendario,6,1),2)+27,"") -> 46200 | X19: =IF(MONTH(DATE(AnoCalendario,6,1)-WEEKDAY(DATE(AnoCalendario,6,1),2)+28)=6,DATE(AnoCalendario,6,1)-WEEKDAY(DATE(AnoCalendario,6,1),2)+28,"") -> 46201
B20: =IF(MONTH(DATE(AnoCalendario,4,1)-WEEKDAY(DATE(AnoCalendario,4,1),2)+29)=4,DATE(AnoCalendario,4,1)-WEEKDAY(DATE(AnoCalendario,4,1),2)+29,"") -> 46139 | C20: =IF(MONTH(DATE(AnoCalendario,4,1)-WEEKDAY(DATE(AnoCalendario,4,1),2)+30)=4,DATE(AnoCalendario,4,1)-WEEKDAY(DATE(AnoCalendario,4,1),2)+30,"") -> 46140 | D20: =IF(MONTH(DATE(AnoCalendario,4,1)-WEEKDAY(DATE(AnoCalendario,4,1),2)+31)=4,DATE(AnoCalendario,4,1)-WEEKDAY(DATE(AnoCalendario,4,1),2)+31,"") -> 46141 | E20: =IF(MONTH(DATE(AnoCalendario,4,1)-WEEKDAY(DATE(AnoCalendario,4,1),2)+32)=4,DATE(AnoCalendario,4,1)-WEEKDAY(DATE(AnoCalendario,4,1),2)+32,"") -> 46142 | F20: =IF(MONTH(DATE(AnoCalendario,4,1)-WEEKDAY(DATE(AnoCalendario,4,1),2)+33)=4,DATE(AnoCalendario,4,1)-WEEKDAY(DATE(AnoCalendario,4,1),2)+33,"") | G20: =IF(MONTH(DATE(AnoCalendario,4,1)-WEEKDAY(DATE(AnoCalendario,4,1),2)+34)=4,DATE(AnoCalendario,4,1)-WEEKDAY(DATE(AnoCalendario,4,1),2)+34,"") | H20: =IF(MONTH(DATE(AnoCalendario,4,1)-WEEKDAY(DATE(AnoCalendario,4,1),2)+35)=4,DATE(AnoCalendario,4,1)-WEEKDAY(DATE(AnoCalendario,4,1),2)+35,"") | J20: =IF(MONTH(DATE(AnoCalendario,5,1)-WEEKDAY(DATE(AnoCalendario,5,1),2)+29)=5,DATE(AnoCalendario,5,1)-WEEKDAY(DATE(AnoCalendario,5,1),2)+29,"") -> 46167 | K20: =IF(MONTH(DATE(AnoCalendario,5,1)-WEEKDAY(DATE(AnoCalendario,5,1),2)+30)=5,DATE(AnoCalendario,5,1)-WEEKDAY(DATE(AnoCalendario,5,1),2)+30,"") -> 46168 | L20: =IF(MONTH(DATE(AnoCalendario,5,1)-WEEKDAY(DATE(AnoCalendario,5,1),2)+31)=5,DATE(AnoCalendario,5,1)-WEEKDAY(DATE(AnoCalendario,5,1),2)+31,"") -> 46169 | M20: =IF(MONTH(DATE(AnoCalendario,5,1)-WEEKDAY(DATE(AnoCalendario,5,1),2)+32)=5,DATE(AnoCalendario,5,1)-WEEKDAY(DATE(AnoCalendario,5,1),2)+32,"") -> 46170 | N20: =IF(MONTH(DATE(AnoCalendario,5,1)-WEEKDAY(DATE(AnoCalendario,5,1),2)+33)=5,DATE(AnoCalendario,5,1)-WEEKDAY(DATE(AnoCalendario,5,1),2)+33,"") -> 46171 | O20: =IF(MONTH(DATE(AnoCalendario,5,1)-WEEKDAY(DATE(AnoCalendario,5,1),2)+34)=5,DATE(AnoCalendario,5,1)-WEEKDAY(DATE(AnoCalendario,5,1),2)+34,"") -> 46172 | P20: =IF(MONTH(DATE(AnoCalendario,5,1)-WEEKDAY(DATE(AnoCalendario,5,1),2)+35)=5,DATE(AnoCalendario,5,1)-WEEKDAY(DATE(AnoCalendario,5,1),2)+35,"") -> 46173 | R20: =IF(MONTH(DATE(AnoCalendario,6,1)-WEEKDAY(DATE(AnoCalendario,6,1),2)+29)=6,DATE(AnoCalendario,6,1)-WEEKDAY(DATE(AnoCalendario,6,1),2)+29,"") -> 46202 | S20: =IF(MONTH(DATE(AnoCalendario,6,1)-WEEKDAY(DATE(AnoCalendario,6,1),2)+30)=6,DATE(AnoCalendario,6,1)-WEEKDAY(DATE(AnoCalendario,6,1),2)+30,"") -> 46203 | T20: =IF(MONTH(DATE(AnoCalendario,6,1)-WEEKDAY(DATE(AnoCalendario,6,1),2)+31)=6,DATE(AnoCalendario,6,1)-WEEKDAY(DATE(AnoCalendario,6,1),2)+31,"") | U20: =IF(MONTH(DATE(AnoCalendario,6,1)-WEEKDAY(DATE(AnoCalendario,6,1),2)+32)=6,DATE(AnoCalendario,6,1)-WEEKDAY(DATE(AnoCalendario,6,1),2)+32,"") | V20: =IF(MONTH(DATE(AnoCalendario,6,1)-WEEKDAY(DATE(AnoCalendario,6,1),2)+33)=6,DATE(AnoCalendario,6,1)-WEEKDAY(DATE(AnoCalendario,6,1),2)+33,"") | W20: =IF(MONTH(DATE(AnoCalendario,6,1)-WEEKDAY(DATE(AnoCalendario,6,1),2)+34)=6,DATE(AnoCalendario,6,1)-WEEKDAY(DATE(AnoCalendario,6,1),2)+34,"") | X20: =IF(MONTH(DATE(AnoCalendario,6,1)-WEEKDAY(DATE(AnoCalendario,6,1),2)+35)=6,DATE(AnoCalendario,6,1)-WEEKDAY(DATE(AnoCalendario,6,1),2)+35,"")
B21: =IF(MONTH(DATE(AnoCalendario,4,1)-WEEKDAY(DATE(AnoCalendario,4,1),2)+36)=4,DATE(AnoCalendario,4,1)-WEEKDAY(DATE(AnoCalendario,4,1),2)+36,"") | C21: =IF(MONTH(DATE(AnoCalendario,4,1)-WEEKDAY(DATE(AnoCalendario,4,1),2)+37)=4,DATE(AnoCalendario,4,1)-WEEKDAY(DATE(AnoCalendario,4,1),2)+37,"") | D21: =IF(MONTH(DATE(AnoCalendario,4,1)-WEEKDAY(DATE(AnoCalendario,4,1),2)+38)=4,DATE(AnoCalendario,4,1)-WEEKDAY(DATE(AnoCalendario,4,1),2)+38,"") | E21: =IF(MONTH(DATE(AnoCalendario,4,1)-WEEKDAY(DATE(AnoCalendario,4,1),2)+39)=4,DATE(AnoCalendario,4,1)-WEEKDAY(DATE(AnoCalendario,4,1),2)+39,"") | F21: =IF(MONTH(DATE(AnoCalendario,4,1)-WEEKDAY(DATE(AnoCalendario,4,1),2)+40)=4,DATE(AnoCalendario,4,1)-WEEKDAY(DATE(AnoCalendario,4,1),2)+40,"") | G21: =IF(MONTH(DATE(AnoCalendario,4,1)-WEEKDAY(DATE(AnoCalendario,4,1),2)+41)=4,DATE(AnoCalendario,4,1)-WEEKDAY(DATE(AnoCalendario,4,1),2)+41,"") | H21: =IF(MONTH(DATE(AnoCalendario,4,1)-WEEKDAY(DATE(AnoCalendario,4,1),2)+42)=4,DATE(AnoCalendario,4,1)-WEEKDAY(DATE(AnoCalendario,4,1),2)+42,"") | J21: =IF(MONTH(DATE(AnoCalendario,5,1)-WEEKDAY(DATE(AnoCalendario,5,1),2)+36)=5,DATE(AnoCalendario,5,1)-WEEKDAY(DATE(AnoCalendario,5,1),2)+36,"") | K21: =IF(MONTH(DATE(AnoCalendario,5,1)-WEEKDAY(DATE(AnoCalendario,5,1),2)+37)=5,DATE(AnoCalendario,5,1)-WEEKDAY(DATE(AnoCalendario,5,1),2)+37,"") | L21: =IF(MONTH(DATE(AnoCalendario,5,1)-WEEKDAY(DATE(AnoCalendario,5,1),2)+38)=5,DATE(AnoCalendario,5,1)-WEEKDAY(DATE(AnoCalendario,5,1),2)+38,"") | M21: =IF(MONTH(DATE(AnoCalendario,5,1)-WEEKDAY(DATE(AnoCalendario,5,1),2)+39)=5,DATE(AnoCalendario,5,1)-WEEKDAY(DATE(AnoCalendario,5,1),2)+39,"") | N21: =IF(MONTH(DATE(AnoCalendario,5,1)-WEEKDAY(DATE(AnoCalendario,5,1),2)+40)=5,DATE(AnoCalendario,5,1)-WEEKDAY(DATE(AnoCalendario,5,1),2)+40,"") | O21: =IF(MONTH(DATE(AnoCalendario,5,1)-WEEKDAY(DATE(AnoCalendario,5,1),2)+41)=5,DATE(AnoCalendario,5,1)-WEEKDAY(DATE(AnoCalendario,5,1),2)+41,"") | P21: =IF(MONTH(DATE(AnoCalendario,5,1)-WEEKDAY(DATE(AnoCalendario,5,1),2)+42)=5,DATE(AnoCalendario,5,1)-WEEKDAY(DATE(AnoCalendario,5,1),2)+42,"") | R21: =IF(MONTH(DATE(AnoCalendario,6,1)-WEEKDAY(DATE(AnoCalendario,6,1),2)+36)=6,DATE(AnoCalendario,6,1)-WEEKDAY(DATE(AnoCalendario,6,1),2)+36,"") | S21: =IF(MONTH(DATE(AnoCalendario,6,1)-WEEKDAY(DATE(AnoCalendario,6,1),2)+37)=6,DATE(AnoCalendario,6,1)-WEEKDAY(DATE(AnoCalendario,6,1),2)+37,"") | T21: =IF(MONTH(DATE(AnoCalendario,6,1)-WEEKDAY(DATE(AnoCalendario,6,1),2)+38)=6,DATE(AnoCalendario,6,1)-WEEKDAY(DATE(AnoCalendario,6,1),2)+38,"") | U21: =IF(MONTH(DATE(AnoCalendario,6,1)-WEEKDAY(DATE(AnoCalendario,6,1),2)+39)=6,DATE(AnoCalendario,6,1)-WEEKDAY(DATE(AnoCalendario,6,1),2)+39,"") | V21: =IF(MONTH(DATE(AnoCalendario,6,1)-WEEKDAY(DATE(AnoCalendario,6,1),2)+40)=6,DATE(AnoCalendario,6,1)-WEEKDAY(DATE(AnoCalendario,6,1),2)+40,"") | W21: =IF(MONTH(DATE(AnoCalendario,6,1)-WEEKDAY(DATE(AnoCalendario,6,1),2)+41)=6,DATE(AnoCalendario,6,1)-WEEKDAY(DATE(AnoCalendario,6,1),2)+41,"") | X21: =IF(MONTH(DATE(AnoCalendario,6,1)-WEEKDAY(DATE(AnoCalendario,6,1),2)+42)=6,DATE(AnoCalendario,6,1)-WEEKDAY(DATE(AnoCalendario,6,1),2)+42,"")
B22: ="Eventos: "&COUNTIFS(Eventos!$A$2:$A$999,">="&DATE(AnoCalendario,4,1),Eventos!$A$2:$A$999,"<"&DATE(AnoCalendario,5,1),Eventos!$H$2:$H$999,"<>Cancelado") -> Eventos: 0 | J22: ="Eventos: "&COUNTIFS(Eventos!$A$2:$A$999,">="&DATE(AnoCalendario,5,1),Eventos!$A$2:$A$999,"<"&DATE(AnoCalendario,6,1),Eventos!$H$2:$H$999,"<>Cancelado") -> Eventos: 0 | R22: ="Eventos: "&COUNTIFS(Eventos!$A$2:$A$999,">="&DATE(AnoCalendario,6,1),Eventos!$A$2:$A$999,"<"&DATE(AnoCalendario,7,1),Eventos!$H$2:$H$999,"<>Cancelado") -> Eventos: 0
B24: ="Julho "&AnoCalendario -> Julho 2026 | J24: ="Agosto "&AnoCalendario -> Agosto 2026 | R24: ="Setembro "&AnoCalendario -> Setembro 2026
B25: Seg | C25: Ter | D25: Qua | E25: Qui | F25: Sex | G25: Sáb | H25: Dom | J25: Seg | K25: Ter | L25: Qua | M25: Qui | N25: Sex | O25: Sáb | P25: Dom | R25: Seg | S25: Ter | T25: Qua | U25: Qui | V25: Sex | W25: Sáb | X25: Dom
B26: =IF(MONTH(DATE(AnoCalendario,7,1)-WEEKDAY(DATE(AnoCalendario,7,1),2)+1)=7,DATE(AnoCalendario,7,1)-WEEKDAY(DATE(AnoCalendario,7,1),2)+1,"") | C26: =IF(MONTH(DATE(AnoCalendario,7,1)-WEEKDAY(DATE(AnoCalendario,7,1),2)+2)=7,DATE(AnoCalendario,7,1)-WEEKDAY(DATE(AnoCalendario,7,1),2)+2,"") | D26: =IF(MONTH(DATE(AnoCalendario,7,1)-WEEKDAY(DATE(AnoCalendario,7,1),2)+3)=7,DATE(AnoCalendario,7,1)-WEEKDAY(DATE(AnoCalendario,7,1),2)+3,"") -> 46204 | E26: =IF(MONTH(DATE(AnoCalendario,7,1)-WEEKDAY(DATE(AnoCalendario,7,1),2)+4)=7,DATE(AnoCalendario,7,1)-WEEKDAY(DATE(AnoCalendario,7,1),2)+4,"") -> 46205 | F26: =IF(MONTH(DATE(AnoCalendario,7,1)-WEEKDAY(DATE(AnoCalendario,7,1),2)+5)=7,DATE(AnoCalendario,7,1)-WEEKDAY(DATE(AnoCalendario,7,1),2)+5,"") -> 46206 | G26: =IF(MONTH(DATE(AnoCalendario,7,1)-WEEKDAY(DATE(AnoCalendario,7,1),2)+6)=7,DATE(AnoCalendario,7,1)-WEEKDAY(DATE(AnoCalendario,7,1),2)+6,"") -> 46207 | H26: =IF(MONTH(DATE(AnoCalendario,7,1)-WEEKDAY(DATE(AnoCalendario,7,1),2)+7)=7,DATE(AnoCalendario,7,1)-WEEKDAY(DATE(AnoCalendario,7,1),2)+7,"") -> 46208 | J26: =IF(MONTH(DATE(AnoCalendario,8,1)-WEEKDAY(DATE(AnoCalendario,8,1),2)+1)=8,DATE(AnoCalendario,8,1)-WEEKDAY(DATE(AnoCalendario,8,1),2)+1,"") | K26: =IF(MONTH(DATE(AnoCalendario,8,1)-WEEKDAY(DATE(AnoCalendario,8,1),2)+2)=8,DATE(AnoCalendario,8,1)-WEEKDAY(DATE(AnoCalendario,8,1),2)+2,"") | L26: =IF(MONTH(DATE(AnoCalendario,8,1)-WEEKDAY(DATE(AnoCalendario,8,1),2)+3)=8,DATE(AnoCalendario,8,1)-WEEKDAY(DATE(AnoCalendario,8,1),2)+3,"") | M26: =IF(MONTH(DATE(AnoCalendario,8,1)-WEEKDAY(DATE(AnoCalendario,8,1),2)+4)=8,DATE(AnoCalendario,8,1)-WEEKDAY(DATE(AnoCalendario,8,1),2)+4,"") | N26: =IF(MONTH(DATE(AnoCalendario,8,1)-WEEKDAY(DATE(AnoCalendario,8,1),2)+5)=8,DATE(AnoCalendario,8,1)-WEEKDAY(DATE(AnoCalendario,8,1),2)+5,"") | O26: =IF(MONTH(DATE(AnoCalendario,8,1)-WEEKDAY(DATE(AnoCalendario,8,1),2)+6)=8,DATE(AnoCalendario,8,1)-WEEKDAY(DATE(AnoCalendario,8,1),2)+6,"") -> 46235 | P26: =IF(MONTH(DATE(AnoCalendario,8,1)-WEEKDAY(DATE(AnoCalendario,8,1),2)+7)=8,DATE(AnoCalendario,8,1)-WEEKDAY(DATE(AnoCalendario,8,1),2)+7,"") -> 46236 | R26: =IF(MONTH(DATE(AnoCalendario,9,1)-WEEKDAY(DATE(AnoCalendario,9,1),2)+1)=9,DATE(AnoCalendario,9,1)-WEEKDAY(DATE(AnoCalendario,9,1),2)+1,"") | S26: =IF(MONTH(DATE(AnoCalendario,9,1)-WEEKDAY(DATE(AnoCalendario,9,1),2)+2)=9,DATE(AnoCalendario,9,1)-WEEKDAY(DATE(AnoCalendario,9,1),2)+2,"") -> 46266 | T26: =IF(MONTH(DATE(AnoCalendario,9,1)-WEEKDAY(DATE(AnoCalendario,9,1),2)+3)=9,DATE(AnoCalendario,9,1)-WEEKDAY(DATE(AnoCalendario,9,1),2)+3,"") -> 46267 | U26: =IF(MONTH(DATE(AnoCalendario,9,1)-WEEKDAY(DATE(AnoCalendario,9,1),2)+4)=9,DATE(AnoCalendario,9,1)-WEEKDAY(DATE(AnoCalendario,9,1),2)+4,"") -> 46268 | V26: =IF(MONTH(DATE(AnoCalendario,9,1)-WEEKDAY(DATE(AnoCalendario,9,1),2)+5)=9,DATE(AnoCalendario,9,1)-WEEKDAY(DATE(AnoCalendario,9,1),2)+5,"") -> 46269 | W26: =IF(MONTH(DATE(AnoCalendario,9,1)-WEEKDAY(DATE(AnoCalendario,9,1),2)+6)=9,DATE(AnoCalendario,9,1)-WEEKDAY(DATE(AnoCalendario,9,1),2)+6,"") -> 46270 | X26: =IF(MONTH(DATE(AnoCalendario,9,1)-WEEKDAY(DATE(AnoCalendario,9,1),2)+7)=9,DATE(AnoCalendario,9,1)-WEEKDAY(DATE(AnoCalendario,9,1),2)+7,"") -> 46271
B27: =IF(MONTH(DATE(AnoCalendario,7,1)-WEEKDAY(DATE(AnoCalendario,7,1),2)+8)=7,DATE(AnoCalendario,7,1)-WEEKDAY(DATE(AnoCalendario,7,1),2)+8,"") -> 46209 | C27: =IF(MONTH(DATE(AnoCalendario,7,1)-WEEKDAY(DATE(AnoCalendario,7,1),2)+9)=7,DATE(AnoCalendario,7,1)-WEEKDAY(DATE(AnoCalendario,7,1),2)+9,"") -> 46210 | D27: =IF(MONTH(DATE(AnoCalendario,7,1)-WEEKDAY(DATE(AnoCalendario,7,1),2)+10)=7,DATE(AnoCalendario,7,1)-WEEKDAY(DATE(AnoCalendario,7,1),2)+10,"") -> 46211 | E27: =IF(MONTH(DATE(AnoCalendario,7,1)-WEEKDAY(DATE(AnoCalendario,7,1),2)+11)=7,DATE(AnoCalendario,7,1)-WEEKDAY(DATE(AnoCalendario,7,1),2)+11,"") -> 46212 | F27: =IF(MONTH(DATE(AnoCalendario,7,1)-WEEKDAY(DATE(AnoCalendario,7,1),2)+12)=7,DATE(AnoCalendario,7,1)-WEEKDAY(DATE(AnoCalendario,7,1),2)+12,"") -> 46213 | G27: =IF(MONTH(DATE(AnoCalendario,7,1)-WEEKDAY(DATE(AnoCalendario,7,1),2)+13)=7,DATE(AnoCalendario,7,1)-WEEKDAY(DATE(AnoCalendario,7,1),2)+13,"") -> 46214 | H27: =IF(MONTH(DATE(AnoCalendario,7,1)-WEEKDAY(DATE(AnoCalendario,7,1),2)+14)=7,DATE(AnoCalendario,7,1)-WEEKDAY(DATE(AnoCalendario,7,1),2)+14,"") -> 46215 | J27: =IF(MONTH(DATE(AnoCalendario,8,1)-WEEKDAY(DATE(AnoCalendario,8,1),2)+8)=8,DATE(AnoCalendario,8,1)-WEEKDAY(DATE(AnoCalendario,8,1),2)+8,"") -> 46237 | K27: =IF(MONTH(DATE(AnoCalendario,8,1)-WEEKDAY(DATE(AnoCalendario,8,1),2)+9)=8,DATE(AnoCalendario,8,1)-WEEKDAY(DATE(AnoCalendario,8,1),2)+9,"") -> 46238 | L27: =IF(MONTH(DATE(AnoCalendario,8,1)-WEEKDAY(DATE(AnoCalendario,8,1),2)+10)=8,DATE(AnoCalendario,8,1)-WEEKDAY(DATE(AnoCalendario,8,1),2)+10,"") -> 46239 | M27: =IF(MONTH(DATE(AnoCalendario,8,1)-WEEKDAY(DATE(AnoCalendario,8,1),2)+11)=8,DATE(AnoCalendario,8,1)-WEEKDAY(DATE(AnoCalendario,8,1),2)+11,"") -> 46240 | N27: =IF(MONTH(DATE(AnoCalendario,8,1)-WEEKDAY(DATE(AnoCalendario,8,1),2)+12)=8,DATE(AnoCalendario,8,1)-WEEKDAY(DATE(AnoCalendario,8,1),2)+12,"") -> 46241 | O27: =IF(MONTH(DATE(AnoCalendario,8,1)-WEEKDAY(DATE(AnoCalendario,8,1),2)+13)=8,DATE(AnoCalendario,8,1)-WEEKDAY(DATE(AnoCalendario,8,1),2)+13,"") -> 46242 | P27: =IF(MONTH(DATE(AnoCalendario,8,1)-WEEKDAY(DATE(AnoCalendario,8,1),2)+14)=8,DATE(AnoCalendario,8,1)-WEEKDAY(DATE(AnoCalendario,8,1),2)+14,"") -> 46243 | R27: =IF(MONTH(DATE(AnoCalendario,9,1)-WEEKDAY(DATE(AnoCalendario,9,1),2)+8)=9,DATE(AnoCalendario,9,1)-WEEKDAY(DATE(AnoCalendario,9,1),2)+8,"") -> 46272 | S27: =IF(MONTH(DATE(AnoCalendario,9,1)-WEEKDAY(DATE(AnoCalendario,9,1),2)+9)=9,DATE(AnoCalendario,9,1)-WEEKDAY(DATE(AnoCalendario,9,1),2)+9,"") -> 46273 | T27: =IF(MONTH(DATE(AnoCalendario,9,1)-WEEKDAY(DATE(AnoCalendario,9,1),2)+10)=9,DATE(AnoCalendario,9,1)-WEEKDAY(DATE(AnoCalendario,9,1),2)+10,"") -> 46274 | U27: =IF(MONTH(DATE(AnoCalendario,9,1)-WEEKDAY(DATE(AnoCalendario,9,1),2)+11)=9,DATE(AnoCalendario,9,1)-WEEKDAY(DATE(AnoCalendario,9,1),2)+11,"") -> 46275 | V27: =IF(MONTH(DATE(AnoCalendario,9,1)-WEEKDAY(DATE(AnoCalendario,9,1),2)+12)=9,DATE(AnoCalendario,9,1)-WEEKDAY(DATE(AnoCalendario,9,1),2)+12,"") -> 46276 | W27: =IF(MONTH(DATE(AnoCalendario,9,1)-WEEKDAY(DATE(AnoCalendario,9,1),2)+13)=9,DATE(AnoCalendario,9,1)-WEEKDAY(DATE(AnoCalendario,9,1),2)+13,"") -> 46277 | X27: =IF(MONTH(DATE(AnoCalendario,9,1)-WEEKDAY(DATE(AnoCalendario,9,1),2)+14)=9,DATE(AnoCalendario,9,1)-WEEKDAY(DATE(AnoCalendario,9,1),2)+14,"") -> 46278
B28: =IF(MONTH(DATE(AnoCalendario,7,1)-WEEKDAY(DATE(AnoCalendario,7,1),2)+15)=7,DATE(AnoCalendario,7,1)-WEEKDAY(DATE(AnoCalendario,7,1),2)+15,"") -> 46216 | C28: =IF(MONTH(DATE(AnoCalendario,7,1)-WEEKDAY(DATE(AnoCalendario,7,1),2)+16)=7,DATE(AnoCalendario,7,1)-WEEKDAY(DATE(AnoCalendario,7,1),2)+16,"") -> 46217 | D28: =IF(MONTH(DATE(AnoCalendario,7,1)-WEEKDAY(DATE(AnoCalendario,7,1),2)+17)=7,DATE(AnoCalendario,7,1)-WEEKDAY(DATE(AnoCalendario,7,1),2)+17,"") -> 46218 | E28: =IF(MONTH(DATE(AnoCalendario,7,1)-WEEKDAY(DATE(AnoCalendario,7,1),2)+18)=7,DATE(AnoCalendario,7,1)-WEEKDAY(DATE(AnoCalendario,7,1),2)+18,"") -> 46219 | F28: =IF(MONTH(DATE(AnoCalendario,7,1)-WEEKDAY(DATE(AnoCalendario,7,1),2)+19)=7,DATE(AnoCalendario,7,1)-WEEKDAY(DATE(AnoCalendario,7,1),2)+19,"") -> 46220 | G28: =IF(MONTH(DATE(AnoCalendario,7,1)-WEEKDAY(DATE(AnoCalendario,7,1),2)+20)=7,DATE(AnoCalendario,7,1)-WEEKDAY(DATE(AnoCalendario,7,1),2)+20,"") -> 46221 | H28: =IF(MONTH(DATE(AnoCalendario,7,1)-WEEKDAY(DATE(AnoCalendario,7,1),2)+21)=7,DATE(AnoCalendario,7,1)-WEEKDAY(DATE(AnoCalendario,7,1),2)+21,"") -> 46222 | J28: =IF(MONTH(DATE(AnoCalendario,8,1)-WEEKDAY(DATE(AnoCalendario,8,1),2)+15)=8,DATE(AnoCalendario,8,1)-WEEKDAY(DATE(AnoCalendario,8,1),2)+15,"") -> 46244 | K28: =IF(MONTH(DATE(AnoCalendario,8,1)-WEEKDAY(DATE(AnoCalendario,8,1),2)+16)=8,DATE(AnoCalendario,8,1)-WEEKDAY(DATE(AnoCalendario,8,1),2)+16,"") -> 46245 | L28: =IF(MONTH(DATE(AnoCalendario,8,1)-WEEKDAY(DATE(AnoCalendario,8,1),2)+17)=8,DATE(AnoCalendario,8,1)-WEEKDAY(DATE(AnoCalendario,8,1),2)+17,"") -> 46246 | M28: =IF(MONTH(DATE(AnoCalendario,8,1)-WEEKDAY(DATE(AnoCalendario,8,1),2)+18)=8,DATE(AnoCalendario,8,1)-WEEKDAY(DATE(AnoCalendario,8,1),2)+18,"") -> 46247 | N28: =IF(MONTH(DATE(AnoCalendario,8,1)-WEEKDAY(DATE(AnoCalendario,8,1),2)+19)=8,DATE(AnoCalendario,8,1)-WEEKDAY(DATE(AnoCalendario,8,1),2)+19,"") -> 46248 | O28: =IF(MONTH(DATE(AnoCalendario,8,1)-WEEKDAY(DATE(AnoCalendario,8,1),2)+20)=8,DATE(AnoCalendario,8,1)-WEEKDAY(DATE(AnoCalendario,8,1),2)+20,"") -> 46249 | P28: =IF(MONTH(DATE(AnoCalendario,8,1)-WEEKDAY(DATE(AnoCalendario,8,1),2)+21)=8,DATE(AnoCalendario,8,1)-WEEKDAY(DATE(AnoCalendario,8,1),2)+21,"") -> 46250 | R28: =IF(MONTH(DATE(AnoCalendario,9,1)-WEEKDAY(DATE(AnoCalendario,9,1),2)+15)=9,DATE(AnoCalendario,9,1)-WEEKDAY(DATE(AnoCalendario,9,1),2)+15,"") -> 46279 | S28: =IF(MONTH(DATE(AnoCalendario,9,1)-WEEKDAY(DATE(AnoCalendario,9,1),2)+16)=9,DATE(AnoCalendario,9,1)-WEEKDAY(DATE(AnoCalendario,9,1),2)+16,"") -> 46280 | T28: =IF(MONTH(DATE(AnoCalendario,9,1)-WEEKDAY(DATE(AnoCalendario,9,1),2)+17)=9,DATE(AnoCalendario,9,1)-WEEKDAY(DATE(AnoCalendario,9,1),2)+17,"") -> 46281 | U28: =IF(MONTH(DATE(AnoCalendario,9,1)-WEEKDAY(DATE(AnoCalendario,9,1),2)+18)=9,DATE(AnoCalendario,9,1)-WEEKDAY(DATE(AnoCalendario,9,1),2)+18,"") -> 46282 | V28: =IF(MONTH(DATE(AnoCalendario,9,1)-WEEKDAY(DATE(AnoCalendario,9,1),2)+19)=9,DATE(AnoCalendario,9,1)-WEEKDAY(DATE(AnoCalendario,9,1),2)+19,"") -> 46283 | W28: =IF(MONTH(DATE(AnoCalendario,9,1)-WEEKDAY(DATE(AnoCalendario,9,1),2)+20)=9,DATE(AnoCalendario,9,1)-WEEKDAY(DATE(AnoCalendario,9,1),2)+20,"") -> 46284 | X28: =IF(MONTH(DATE(AnoCalendario,9,1)-WEEKDAY(DATE(AnoCalendario,9,1),2)+21)=9,DATE(AnoCalendario,9,1)-WEEKDAY(DATE(AnoCalendario,9,1),2)+21,"") -> 46285
B29: =IF(MONTH(DATE(AnoCalendario,7,1)-WEEKDAY(DATE(AnoCalendario,7,1),2)+22)=7,DATE(AnoCalendario,7,1)-WEEKDAY(DATE(AnoCalendario,7,1),2)+22,"") -> 46223 | C29: =IF(MONTH(DATE(AnoCalendario,7,1)-WEEKDAY(DATE(AnoCalendario,7,1),2)+23)=7,DATE(AnoCalendario,7,1)-WEEKDAY(DATE(AnoCalendario,7,1),2)+23,"") -> 46224 | D29: =IF(MONTH(DATE(AnoCalendario,7,1)-WEEKDAY(DATE(AnoCalendario,7,1),2)+24)=7,DATE(AnoCalendario,7,1)-WEEKDAY(DATE(AnoCalendario,7,1),2)+24,"") -> 46225 | E29: =IF(MONTH(DATE(AnoCalendario,7,1)-WEEKDAY(DATE(AnoCalendario,7,1),2)+25)=7,DATE(AnoCalendario,7,1)-WEEKDAY(DATE(AnoCalendario,7,1),2)+25,"") -> 46226 | F29: =IF(MONTH(DATE(AnoCalendario,7,1)-WEEKDAY(DATE(AnoCalendario,7,1),2)+26)=7,DATE(AnoCalendario,7,1)-WEEKDAY(DATE(AnoCalendario,7,1),2)+26,"") -> 46227 | G29: =IF(MONTH(DATE(AnoCalendario,7,1)-WEEKDAY(DATE(AnoCalendario,7,1),2)+27)=7,DATE(AnoCalendario,7,1)-WEEKDAY(DATE(AnoCalendario,7,1),2)+27,"") -> 46228 | H29: =IF(MONTH(DATE(AnoCalendario,7,1)-WEEKDAY(DATE(AnoCalendario,7,1),2)+28)=7,DATE(AnoCalendario,7,1)-WEEKDAY(DATE(AnoCalendario,7,1),2)+28,"") -> 46229 | J29: =IF(MONTH(DATE(AnoCalendario,8,1)-WEEKDAY(DATE(AnoCalendario,8,1),2)+22)=8,DATE(AnoCalendario,8,1)-WEEKDAY(DATE(AnoCalendario,8,1),2)+22,"") -> 46251 | K29: =IF(MONTH(DATE(AnoCalendario,8,1)-WEEKDAY(DATE(AnoCalendario,8,1),2)+23)=8,DATE(AnoCalendario,8,1)-WEEKDAY(DATE(AnoCalendario,8,1),2)+23,"") -> 46252 | L29: =IF(MONTH(DATE(AnoCalendario,8,1)-WEEKDAY(DATE(AnoCalendario,8,1),2)+24)=8,DATE(AnoCalendario,8,1)-WEEKDAY(DATE(AnoCalendario,8,1),2)+24,"") -> 46253 | M29: =IF(MONTH(DATE(AnoCalendario,8,1)-WEEKDAY(DATE(AnoCalendario,8,1),2)+25)=8,DATE(AnoCalendario,8,1)-WEEKDAY(DATE(AnoCalendario,8,1),2)+25,"") -> 46254 | N29: =IF(MONTH(DATE(AnoCalendario,8,1)-WEEKDAY(DATE(AnoCalendario,8,1),2)+26)=8,DATE(AnoCalendario,8,1)-WEEKDAY(DATE(AnoCalendario,8,1),2)+26,"") -> 46255 | O29: =IF(MONTH(DATE(AnoCalendario,8,1)-WEEKDAY(DATE(AnoCalendario,8,1),2)+27)=8,DATE(AnoCalendario,8,1)-WEEKDAY(DATE(AnoCalendario,8,1),2)+27,"") -> 46256 | P29: =IF(MONTH(DATE(AnoCalendario,8,1)-WEEKDAY(DATE(AnoCalendario,8,1),2)+28)=8,DATE(AnoCalendario,8,1)-WEEKDAY(DATE(AnoCalendario,8,1),2)+28,"") -> 46257 | R29: =IF(MONTH(DATE(AnoCalendario,9,1)-WEEKDAY(DATE(AnoCalendario,9,1),2)+22)=9,DATE(AnoCalendario,9,1)-WEEKDAY(DATE(AnoCalendario,9,1),2)+22,"") -> 46286 | S29: =IF(MONTH(DATE(AnoCalendario,9,1)-WEEKDAY(DATE(AnoCalendario,9,1),2)+23)=9,DATE(AnoCalendario,9,1)-WEEKDAY(DATE(AnoCalendario,9,1),2)+23,"") -> 46287 | T29: =IF(MONTH(DATE(AnoCalendario,9,1)-WEEKDAY(DATE(AnoCalendario,9,1),2)+24)=9,DATE(AnoCalendario,9,1)-WEEKDAY(DATE(AnoCalendario,9,1),2)+24,"") -> 46288 | U29: =IF(MONTH(DATE(AnoCalendario,9,1)-WEEKDAY(DATE(AnoCalendario,9,1),2)+25)=9,DATE(AnoCalendario,9,1)-WEEKDAY(DATE(AnoCalendario,9,1),2)+25,"") -> 46289 | V29: =IF(MONTH(DATE(AnoCalendario,9,1)-WEEKDAY(DATE(AnoCalendario,9,1),2)+26)=9,DATE(AnoCalendario,9,1)-WEEKDAY(DATE(AnoCalendario,9,1),2)+26,"") -> 46290 | W29: =IF(MONTH(DATE(AnoCalendario,9,1)-WEEKDAY(DATE(AnoCalendario,9,1),2)+27)=9,DATE(AnoCalendario,9,1)-WEEKDAY(DATE(AnoCalendario,9,1),2)+27,"") -> 46291 | X29: =IF(MONTH(DATE(AnoCalendario,9,1)-WEEKDAY(DATE(AnoCalendario,9,1),2)+28)=9,DATE(AnoCalendario,9,1)-WEEKDAY(DATE(AnoCalendario,9,1),2)+28,"") -> 46292
B30: =IF(MONTH(DATE(AnoCalendario,7,1)-WEEKDAY(DATE(AnoCalendario,7,1),2)+29)=7,DATE(AnoCalendario,7,1)-WEEKDAY(DATE(AnoCalendario,7,1),2)+29,"") -> 46230 | C30: =IF(MONTH(DATE(AnoCalendario,7,1)-WEEKDAY(DATE(AnoCalendario,7,1),2)+30)=7,DATE(AnoCalendario,7,1)-WEEKDAY(DATE(AnoCalendario,7,1),2)+30,"") -> 46231 | D30: =IF(MONTH(DATE(AnoCalendario,7,1)-WEEKDAY(DATE(AnoCalendario,7,1),2)+31)=7,DATE(AnoCalendario,7,1)-WEEKDAY(DATE(AnoCalendario,7,1),2)+31,"") -> 46232 | E30: =IF(MONTH(DATE(AnoCalendario,7,1)-WEEKDAY(DATE(AnoCalendario,7,1),2)+32)=7,DATE(AnoCalendario,7,1)-WEEKDAY(DATE(AnoCalendario,7,1),2)+32,"") -> 46233 | F30: =IF(MONTH(DATE(AnoCalendario,7,1)-WEEKDAY(DATE(AnoCalendario,7,1),2)+33)=7,DATE(AnoCalendario,7,1)-WEEKDAY(DATE(AnoCalendario,7,1),2)+33,"") -> 46234 | G30: =IF(MONTH(DATE(AnoCalendario,7,1)-WEEKDAY(DATE(AnoCalendario,7,1),2)+34)=7,DATE(AnoCalendario,7,1)-WEEKDAY(DATE(AnoCalendario,7,1),2)+34,"") | H30: =IF(MONTH(DATE(AnoCalendario,7,1)-WEEKDAY(DATE(AnoCalendario,7,1),2)+35)=7,DATE(AnoCalendario,7,1)-WEEKDAY(DATE(AnoCalendario,7,1),2)+35,"") | J30: =IF(MONTH(DATE(AnoCalendario,8,1)-WEEKDAY(DATE(AnoCalendario,8,1),2)+29)=8,DATE(AnoCalendario,8,1)-WEEKDAY(DATE(AnoCalendario,8,1),2)+29,"") -> 46258 | K30: =IF(MONTH(DATE(AnoCalendario,8,1)-WEEKDAY(DATE(AnoCalendario,8,1),2)+30)=8,DATE(AnoCalendario,8,1)-WEEKDAY(DATE(AnoCalendario,8,1),2)+30,"") -> 46259 | L30: =IF(MONTH(DATE(AnoCalendario,8,1)-WEEKDAY(DATE(AnoCalendario,8,1),2)+31)=8,DATE(AnoCalendario,8,1)-WEEKDAY(DATE(AnoCalendario,8,1),2)+31,"") -> 46260 | M30: =IF(MONTH(DATE(AnoCalendario,8,1)-WEEKDAY(DATE(AnoCalendario,8,1),2)+32)=8,DATE(AnoCalendario,8,1)-WEEKDAY(DATE(AnoCalendario,8,1),2)+32,"") -> 46261 | N30: =IF(MONTH(DATE(AnoCalendario,8,1)-WEEKDAY(DATE(AnoCalendario,8,1),2)+33)=8,DATE(AnoCalendario,8,1)-WEEKDAY(DATE(AnoCalendario,8,1),2)+33,"") -> 46262 | O30: =IF(MONTH(DATE(AnoCalendario,8,1)-WEEKDAY(DATE(AnoCalendario,8,1),2)+34)=8,DATE(AnoCalendario,8,1)-WEEKDAY(DATE(AnoCalendario,8,1),2)+34,"") -> 46263 | P30: =IF(MONTH(DATE(AnoCalendario,8,1)-WEEKDAY(DATE(AnoCalendario,8,1),2)+35)=8,DATE(AnoCalendario,8,1)-WEEKDAY(DATE(AnoCalendario,8,1),2)+35,"") -> 46264 | R30: =IF(MONTH(DATE(AnoCalendario,9,1)-WEEKDAY(DATE(AnoCalendario,9,1),2)+29)=9,DATE(AnoCalendario,9,1)-WEEKDAY(DATE(AnoCalendario,9,1),2)+29,"") -> 46293 | S30: =IF(MONTH(DATE(AnoCalendario,9,1)-WEEKDAY(DATE(AnoCalendario,9,1),2)+30)=9,DATE(AnoCalendario,9,1)-WEEKDAY(DATE(AnoCalendario,9,1),2)+30,"") -> 46294 | T30: =IF(MONTH(DATE(AnoCalendario,9,1)-WEEKDAY(DATE(AnoCalendario,9,1),2)+31)=9,DATE(AnoCalendario,9,1)-WEEKDAY(DATE(AnoCalendario,9,1),2)+31,"") -> 46295 | U30: =IF(MONTH(DATE(AnoCalendario,9,1)-WEEKDAY(DATE(AnoCalendario,9,1),2)+32)=9,DATE(AnoCalendario,9,1)-WEEKDAY(DATE(AnoCalendario,9,1),2)+32,"") | V30: =IF(MONTH(DATE(AnoCalendario,9,1)-WEEKDAY(DATE(AnoCalendario,9,1),2)+33)=9,DATE(AnoCalendario,9,1)-WEEKDAY(DATE(AnoCalendario,9,1),2)+33,"") | W30: =IF(MONTH(DATE(AnoCalendario,9,1)-WEEKDAY(DATE(AnoCalendario,9,1),2)+34)=9,DATE(AnoCalendario,9,1)-WEEKDAY(DATE(AnoCalendario,9,1),2)+34,"") | X30: =IF(MONTH(DATE(AnoCalendario,9,1)-WEEKDAY(DATE(AnoCalendario,9,1),2)+35)=9,DATE(AnoCalendario,9,1)-WEEKDAY(DATE(AnoCalendario,9,1),2)+35,"")
